Workbook

Sheet 01_표지·목차
A1: 태양광 발전량 성능진단 기준모델
A2: 지역별 일사량 → 경사면 일사량(POA) → 발전량 → 성능진단으로 이어지는 계산 기준을 정의하는 통합 워크북입니다.
A4: ■ 문서 정보
A5: 문서 버전 | B5: v1.0 | E5: 본 워크북 정리 버전
A6: 모델 버전 | B6: MVP-0.2.0 | E6: 웹 프로그램(app.py)과 공유하는 계산모델 버전
A7: 작성 기준일 | B7: 2026-08-03 | E7: 버전이력 시트 참조
A8: 분석 기간 | B8: 2016년 1월 ~ 2025년 12월 (10개년) | E8: 연 단위 완전 데이터
A9: 대상 지역 | B9: 10개 권역 (서울경기·강원영동·강원영서·충북·충남·경북·경남·전북·전남·제주)
A10: 자료 출처 | B10: 기상청 기상자료개방포털 「기후통계분석 - 일조일사」 (data.kma.go.kr) | E10: MJ/m² ÷ 3.6 = kWh/m²
A11: 용도 | B11: 예비 타당성·성능진단용 기준모델 | E11: 금융·성능보증용은 시간별 현장자료 적용 필요
A13: ■ 요약 지표 (2016~2025 실측 자료 기준, 자동 계산)
A14: 연평균 일사량 최고 권역 | B14: =INDEX('22_피벗_연도별'!$B$3:$K$3,MATCH(MAX('22_피벗_연도별'!$B$14:$K$14),'22_피벗_연도별'!$B$14:$K$14,0)) | D14: =MAX('22_피벗_연도별'!$B$14:$K$14) | E14: kWh/m²/년
A15: 일평균 일사량 최고 권역 | B15: =INDEX('22_피벗_연도별'!$O$3:$X$3,MATCH(MAX('22_피벗_연도별'!$O$14:$X$14),'22_피벗_연도별'!$O$14:$X$14,0)) | D15: =MAX('22_피벗_연도별'!$O$14:$X$14) | E15: kWh/m²/일
A16: 전국 평균 일사량 | B16: 10개 권역 평균 | D16: =AVERAGE('22_피벗_연도별'!$L$4:$L$13) | E16: kWh/m²/년
A17: 일사량 최대 월(계절 패턴) | B17: =INDEX('23_피벗_계절패턴'!$A$4:$A$15,MATCH(MAX('23_피벗_계절패턴'!$L$4:$L$15),'23_피벗_계절패턴'!$L$4:$L$15,0))&"월" | D17: =MAX('23_피벗_계절패턴'!$L$4:$L$15) | E17: kWh/m²/월
A18: 일사량 최소 월(계절 패턴) | B18: =INDEX('23_피벗_계절패턴'!$A$4:$A$15,MATCH(MIN('23_피벗_계절패턴'!$L$4:$L$15),'23_피벗_계절패턴'!$L$4:$L$15,0))&"월" | D18: =MIN('23_피벗_계절패턴'!$L$4:$L$15) | E18: kWh/m²/월
A19: 현재 입력 기준 연간 발전량 | B19: ='11_발전량_모델'!$B$5&" / 경사 "&'11_발전량_모델'!$B$7&"° / 방위 "&'11_발전량_모델'!$B$8&"°" | D19: ='11_발전량_모델'!$F$9 | E19: MWh/년
A21: ■ 시트 목차
A22: No. | B22: 시트 | C22: 내용
A23: 01 | B23: 01_표지·목차 | C23: 문서 개요, 요약 지표, 시트 목차 | F23: 표지
A24: 02 | B24: 02_버전이력 | C24: 모델·문서 버전 이력 및 구버전 시트 매핑 | F24: 기준문서
A25: 03 | B25: 03_모델개요 | C25: 간편·상세·전문가 모드별 기능과 구현 범위 | F25: 기준문서
A26: 04 | B26: 04_계산식_명세 | C26: 월별 계산 순서와 계산식 정의(코드·Excel 공통) | F26: 기준문서
A27: 05 | B27: 05_FACTOR_기준값 | C27: 손실 FACTOR 기본값·권장범위·적용 기준 | F27: 기준문서
A28: 06 | B28: 06_진단규칙 | C28: 저하원인 진단규칙과 임계값 | F28: 기준문서
A29: 07 | B29: 07_데이터사전 | C29: 입력·출력 데이터 사전(API/보고서 공통) | F29: 기준문서
A30: 08 | B30: 08_검증CASE | C30: 계산·진단 검증 CASE 및 허용오차 | F30: 기준문서
A31: 09 | B31: 09_보고서구성 | C31: PDF·PPT·Excel 산출물 구성 | F31: 기준문서
A32: 10 | B32: 10_개발연계 | C32: 웹 프로그램 연계 컴포넌트와 검증 방법 | F32: 기준문서
A33: 11 | B33: 11_발전량_모델 | C33: 지역·경사·방위·PR 입력 → 월/연간 POA 및 발전량 계산 | F33: 계산모델
A34: 12 | B34: 12_월별FACTOR | C34: 월별 H0·Kt·산란비·Rb·View Factor 확인 | F34: 계산모델
... A43: 24 | B43: 24_차트 | C43: 연도별 추이·계절 패턴 그래프 | F43: 데이터
A45: ※ 노란 배경·파란 글씨 셀만 사용자가 직접 입력하는 값이며, 그 외 셀은 수식으로 계산됩니다. 초록 글씨는 다른 시트를 참조하는 값입니다.

Sheet 02_버전이력
A1: 버전 이력
A2: 모델 버전과 문서 버전을 함께 관리하며, 계산식이 바뀌면 반드시 버전을 함께 갱신합니다.
A4: ■ 버전 이력
A5: 모델 버전 | B5: 일자 | C5: 구분 | D5: 변경 내용 | E5: 검증 상태 | F5: 프로그램 반영
A6: 문서 v1.0 | B6: 2026-08-03 | C6: 자료 정리 | D6: AI 생성 자료 2건을 단일 워크북으로 재구성(시트 순서·명명·서식 통일, 중복 정의 제거, 보조 계산 분리) | E6: 완료 | F6: 해당 없음
A7: MVP-0.1.0 | B7: 2026-08-03 | C7: 최초 MVP | D7: 간편·상세·전문가 모드, 월간 POA, PDF/PPT/Excel 산출 | E7: 완료 | F7: 완료
A8: MVP-0.2.0 | B8: 2026-08-03 | C8: 기능·품질 개선 | D8: 부분연도 동일기간 비교, 결측월 null 처리, SQLite 프로젝트 저장, 전문가 이미지 부록, PptxGenJS | E8: 완료 | F8: 완료
A9: NEXT | B9: 미정 | C9: 후속 | D9: 시간단위 pvlib 엔진, 주소/지도 입력, 유사 발전소 벤치마크, Windows 단일 실행형 | E9: 미착수 | F9: 미착수
A11: ■ 구버전 → v1.0 시트 매핑
A12: 구버전 시트 | B12: v1.0 시트 | C12: 정리 내용
A13: 버전관리 | B13: 02_버전이력 | C13: v1.0 이력 및 시트 매핑 추가
A14: 프로그램_개요 | B14: 03_모델개요 | C14: 그대로 유지
A15: 계산식_명세 | B15: 04_계산식_명세 | C15: 계산_가이드의 '모델 흐름' 통합
A16: FACTOR_정의 | B16: 05_FACTOR_기준값 | C16: 지역_설정에 중복 정의되던 기본값의 단일 출처로 지정
A17: 진단규칙_명세 | B17: 06_진단규칙 | C17: 그대로 유지
A18: 데이터_사전 | B18: 07_데이터사전 | C18: 그대로 유지
A19: 검증_CASE | B19: 08_검증CASE | C19: 중복된 CASE ID(TC-012 2건) 정정, 일련번호 재부여
A20: 보고서_구성 | B20: 09_보고서구성 | C20: 그대로 유지
A21: 개발_연계 | B21: 10_개발연계 | C21: 그대로 유지
A22: 표지 | B22: 01_표지·목차 | C22: 문서 맨 앞으로 이동, 목차 하이퍼링크·요약지표 추가
A23: 발전량_모델 | B23: 11_발전량_모델 | C23: 입력/결과 영역 구분, 입력 셀 표시 및 유효성 목록 추가
... A33: 차트 | B33: 24_차트 | C33: 통합 피벗을 참조하도록 재작성

Sheet 03_모델개요
A1: 모델 개요 및 모드별 기능
A2: 웹 프로그램, 상세 계산 Excel, 고객 PDF/PPT가 공유해야 하는 분석 원칙과 모드별 기능을 정의합니다.
A4: ■ 모드별 기능 정의
A5: 구분 | B5: 간편 모드 | C5: 상세 모드 | D5: 전문가 모드 | E5: 구현 상태(MVP) | F5: 후속 개발
A6: 주요 목적 | B6: 지역 장기평균 및 분석연도 기상 대비 실제 발전량 비교 | C6: 현장 일사량·설비·인버터 정보를 추가해 원인 후보 검토 | D6: 시간자료·항목별 손실·전문가 의견 및 보고서 편집 | E6: 구현 | F6: 유사 발전소 벤치마크
A7: 최소 입력 | B7: 지역, 분석연도, DC/AC 용량, 실제 월별 발전량 | C7: 간편 입력 + 경사/방위, 모듈, 일사량, 인버터별 연간자료 | D7: 상세 입력 + 시간자료, MPPT, 상태코드, 전문가 손실 FACTOR | E7: 구현 | F7: 시간자료 상세 진단
A8: 기상 기준 | B8: 2016~2025 지역별 GHI 평균 및 선택연도 GHI | C8: 현장 GHI 또는 POA 우선 | D8: 현장 POA·시간별 GHI/DNI/DHI 및 전사모델 선택 | E8: 월 단위 구현 | F8: pvlib 시간엔진
A9: 예상 발전량 | B9: PR 기반 | C9: PR 기반 또는 현장자료 보정 | D9: 항목별 손실 기반 선택 | E9: 구현 | F9: 모듈/인버터 사양 DB
A10: 진단 결과 | B10: 정상/관찰/주의/점검권고, 기본 원인 후보 | C10: 인버터 편차·출력제한·클리핑 가능성 추가 | D10: 진단규칙 임계값과 전문가 의견 관리 | E10: 기본 규칙 구현 | F10: 이상감지 학습모델
A11: 다운로드 | B11: 고객 PDF, PPT, 상세 Excel, JSON | C11: 동일 | D11: 전문가 의견·현장사진 추가용 PPT | E11: 구현(전문가 이미지 부록 포함) | F11: 슬라이드 선택·브랜드 템플릿
A12: 데이터 등급 | B12: D 또는 C | C12: C 또는 B | D12: B 또는 A | E12: 구현 | F12: 자동 품질점수 고도화
A13: 권한 | B13: 고객 | C13: 고객/분석자 | D13: 전문가 PIN 및 서버 토큰 | E13: 서명 토큰·8시간 만료 구현 | F13: 회원·조직·RBAC
A14: 로컬 저장 | B14: 브라우저 입력값 임시보관 | C14: 로컬 SQLite 프로젝트 저장·불러오기 | D14: 전문가 첨부파일 로컬 저장 | E14: 구현 | F14: 백업·복구/다중 사용자

Sheet 04_계산식_명세
A1: 계산식 명세
A2: 프로그램 코드(app.py)와 Excel 기준모델이 동일하게 사용해야 하는 월별 계산 순서입니다. 실제 PR은 현장 POA가 있을 때만 표시합니다.
A4: ■ 모델 흐름
A5: 순서 | B5: 단계 | C5: 내용
A6: ① | B6: 수평면 일사량 선택 | C6: 지역·연도별 월 합계 GHI(원자료 또는 현장 실측)
A7: ② | B7: 월 일평균 환산 | C7: H = 월 GHI ÷ 해당 월 일수
A8: ③ | B8: 태양기하 계산 | C8: 대표 위도·월 대표일로 적위 δ, 일몰시간각 ωs, 대기권외 일사량 H0
A9: ④ | B9: 확산 분리 | C9: Kt = H/H0 → Erbs 월평균 상관식으로 산란비 Hd/H 추정
A10: ⑤ | B10: 직달 전사 | C10: 15분 간격 태양벡터 적분으로 Rb 계산
A11: ⑥ | B11: 경사면 일사량 | C11: POA = 직달 + 천공산란 + 지면반사
A12: ⑦ | B12: 발전량 산정 | C12: POA × DC용량 × PR × 가동률 × (1-출력제한) × 기타보정
A14: ■ 계산식 상세
A15: 순서 | B15: 계산 항목 | C15: 코드 변수 | D15: 수식/알고리즘 | E15: 단위 | F15: 적용 모드 | G15: 입력/출처 | H15: 예외·주의
A16: 1 | B16: 대표일 | C16: representative_day | D16: 1~12월 대표일: 17, 47, 75, 105, 135, 162, 198, 228, 258, 288, 318, 344 | E16: Julian day | F16: 전체 | G16: 월 | H16: 월평균 모델용
A17: 2 | B17: 태양 적위 | C17: delta | D17: δ = 23.45 × sin[360 × (284+n)/365] | E17: degree | F17: 전체 | G17: 대표일 | H17: 각도 계산 시 radian 변환
A18: 3 | B18: 일몰시간각 | C18: omega_s | D18: ωs = acos(-tanφ × tanδ) | E18: radian | F18: 전체 | G18: 위도 φ | H18: acos 인수 -1~1 제한
A19: 4 | B19: 대기권외 일사량 | C19: h0_daily | D19: H0 = (24×60/π)×Gsc×dr×[ωs sinφ sinδ + cosφ cosδ sinωs] ÷ 3.6 | E19: kWh/m²/day | F19: 전체 | G19: Gsc=0.082 MJ/m²/min | H19: 0 이하 방지
A20: 5 | B20: 수평면 일평균 | C20: h_daily | D20: H = 월 GHI ÷ 월 일수 | E20: kWh/m²/day | F20: 전체 | G20: 지역/현장 GHI | H20: 결측을 0으로 대체하지 않음
A21: 6 | B21: 청명도지수 | C21: kt_raw / kt_applied | D21: Kt_raw = H/H0; Erbs 적용 Kt = MAX(0.30, MIN(0.80, Kt_raw)) | E21: - | F21: 전체 | G21: H, H0 | H21: 원자료 Kt와 적용 Kt를 모두 저장
A22: 7 | B22: 산란비 | C22: diffuse_fraction | D22: ωs ≤ 81.4°: 1.391-3.560Kt+4.189Kt²-2.137Kt³ / 그 외: 1.311-3.022Kt+3.427Kt²-1.821Kt³ | E22: - | F22: 전체 | G22: Erbs 월평균식 | H22: 0.05~1.00 제한
A23: 8 | B23: 직달·산란 분리 | C23: beam / diffuse | D23: Hd = H×Kd, Hb = MAX(0, H-Hd) | E23: kWh/m²/day | F23: 전체 | G23: H, Kd | H23: 월평균 분리값
A24: 9 | B24: 직달 경사계수 | C24: rb | D24: 15분 간격 태양벡터 적분: Rb = Σmax(cosθ,0) / Σmax(cosθz,0) | E24: - | F24: 전체 | G24: 위도, 경사각 β, 방위각 A | H24: 방위각 북0 동90 남180 서270
A25: 10 | B25: 천공 View Factor | C25: sky_factor | D25: (1+cosβ)/2 | E25: - | F25: 전체 | G25: 경사각 | H25: 등방성 천공 모델
A26: 11 | B26: 지면 View Factor | C26: ground_factor | D26: (1-cosβ)/2 | E26: - | F26: 전체 | G26: 경사각 | H26: 지면반사율 별도 적용
A27: 12 | B27: 경사면 일사량 | C27: poa_month | D27: POA = [Hb×Rb + Hd×sky_factor + H×ρg×ground_factor] × 일수 | E27: kWh/m²/month | F27: 전체 | G27: GHI, 경사, 방위, 반사율 | H27: 현장 POA 입력 시 계산값보다 우선
... A37: 22 | B37: 자료 커버리지 | C37: coverage_pct | D37: 실제 발전량 입력 월수 ÷ 12 × 100 | E37: % | F37: 전체 | G37: actual_month_count | H37: 부분연도 판정 문구에 표시

Sheet 05_FACTOR_기준값
A1: FACTOR 기준값
A2: FACTOR 기본값의 단일 출처(single source) 시트입니다. 관리자 설정값으로 관리하고 분석 실행 시 스냅샷을 보관합니다.
A4: ■ 손실·보정 FACTOR 기본값
A5: 코드 | B5: 한글명 | C5: 기본값 | D5: 권장범위 | E5: 단위 | F5: 적용방식 | G5: 포함/제외 범위 | H5: 근거·주의 | I5: 출처 URL
A6: pr | B6: 기준 PR | C6: 0.8 | D6: 0.75~0.85 | E6: - | F6: PR 기반 | G6: 정상 설비의 온도·변환·배선 등 종합손실 | H6: 발전소 설계 및 운영수준에 맞게 조정 | I6: https://pvpmc.sandia.gov/modeling-guide/5-ac-system-output/pv-performance-metrics/performance-ratio/
A7: availability | B7: 가동률 | C7: 0.995 | D7: 0.95~1.00 | E7: - | F7: 공통 | G7: 고장·정비로 발전 불가능한 시간 | H7: PR과 별도 적용 시 정의 일관성 필요
A8: curtailment_rate | B8: 출력제한률 | C8: 0 | D8: 0~0.10 | E8: - | F8: 공통 | G8: 계통·계약·운영 지시에 의한 의도적 감발 | H8: 고장·정비는 포함하지 않음
A9: other_factor | B9: 기타보정계수 | C9: 1 | D9: 0.90~1.05 | E9: - | F9: 공통 | G9: 별도 안전계수 또는 프로젝트 특수보정 | H9: PR 손실과 중복 금지
A10: annual_degradation_rate | B10: 연간 모듈 열화율 | C10: 0.005 | D10: 모듈 보증값 | E10: /year | F10: 공통 | G10: 운영연수 보정 | H10: 실제 장기추세와 비교
A11: albedo | B11: 지면반사율 | C11: 0.2 | D11: 0.15~0.30 | E11: - | F11: POA | G11: 지면반사 성분 | H11: 적설·밝은 지붕은 별도 검토 | I11: https://pvpmc.sandia.gov/modeling-guide/1-weather-design-inputs/plane-of-array-poa-irradiance/
A12: iam | B12: 입사각 FACTOR | C12: 0.98 | D12: 0.95~1.00 | E12: - | F12: 항목별 | G12: 입사각 광학손실 | H12: PR 방식에서는 중복 적용 금지
A13: shading | B13: 음영 FACTOR | C13: 0.99 | D13: 0.80~1.00 | E13: - | F13: 항목별 | G13: 주변 지형·구조물 음영 | H13: 시간대별 또는 음영해석 권장
A14: soiling | B14: 오염 FACTOR | C14: 0.97 | D14: 0.90~1.00 | E14: - | F14: 항목별 | G14: 먼지·조류분변·염해 | H14: 강우·세척 전후 성능 확인
A15: temperature | B15: 온도 FACTOR | C15: 0.94 | D15: 0.85~0.98 | E15: - | F15: 항목별 | G15: 모듈 고온 손실 | H15: 시간별 기온·풍속·모듈온도 적용 권장
A16: mismatch | B16: 불일치 FACTOR | C16: 0.98 | D16: 0.95~1.00 | E16: - | F16: 항목별 | G16: 모듈·스트링 전기적 불일치 | H16: MPPT 데이터가 있으면 실측 진단
A17: dc_wiring | B17: DC 배선 FACTOR | C17: 0.985 | D17: 0.97~1.00 | E17: - | F17: 항목별 | G17: DC 케이블·접속 손실 | H17: 설계 전압강하 자료 확인
A18: inverter | B18: 인버터 FACTOR | C18: 0.975 | D18: 0.95~0.99 | E18: - | F18: 항목별 | G18: DC-AC 변환효율 | H18: 클리핑은 별도 또는 모델 내 포함 정의 필요
A19: ac_wiring | B19: AC 배선 FACTOR | C19: 0.99 | D19: 0.98~1.00 | E19: - | F19: 항목별 | G19: AC 배선 손실 | H19: 계량기 위치 확인
A20: transformer | B20: 변압기 FACTOR | C20: 0.99 | D20: 0.97~1.00 | E20: - | F20: 항목별 | G20: 변압기 손실 | H20: 발전량 계측 위치에 따라 제외 가능
A22: ※ PR 기반 방식(간편·상세)과 항목별 손실 방식(전문가)은 동시에 적용하지 않습니다. PR에 이미 포함된 손실을 항목별로 다시 차감하면 이중 차감이 됩니다.
A23: ※ 기준 PR·가동률·지면반사율은 본 시트가 기준이며, '14_지역·상수' 시트의 기본값과 '11_발전량_모델' 시트의 기본 입력값은 이 값을 참조합니다.
A24: ※ 출처가 비어 있는 항목은 프로젝트 관리자 설정값이며, 실제 설비 사양·운영 기록으로 대체하는 것을 권장합니다.

Sheet 06_진단규칙
A1: 저하원인 진단규칙
A2: 진단은 고장 확정이 아니라 가능성·근거·추가 확인·권장조치로 출력합니다. 필요 데이터가 없으면 '판단자료 부족'으로 반환합니다.
A4: ■ 진단규칙 및 임계값
A5: 규칙코드 | B5: 원인명 | C5: 필요 데이터 | D5: 조건/임계값(MVP) | E5: 가능성 | F5: 자동 근거 | G5: 추가 확인 | H5: 권장 조치 | I5: 구현
A6: WEATHER_LOW | B6: 분석연도 일사량 부족 | C6: 지역/현장 GHI | D6: 연간 GHI ÷ 10년평균 GHI < 0.96 | E6: 보통~높음 | F6: 분석연도와 장기평균 일사량 비율 | G6: 현장 POA, 인근 관측소 거리 | H6: 기상영향과 설비성능 차이를 분리 | I6: 구현
A7: PERF_LOW | B7: 기상 보정 후 성능저하 | C7: 실제 발전량, 기상보정 예상량 | D7: 연간 PI < 0.97 (<0.92 보통, <0.85 높음) | E7: 낮음~높음 | F7: 실제/예상 비율과 저하월 목록 | G7: 정지·알람·세척·출력제한 | H7: 설비 및 운영 기록 순차 점검 | I7: 구현
A8: INV_LOW | B8: 특정 인버터 저하 | C8: 인버터별 DC용량, 연간발전량 | D8: 특성발전량이 중앙값 대비 -7% 이하 | E8: 보통~높음 | F8: 인버터별 kWh/kWp 편차 | G8: MPPT 전류, 알람, 차단기 | H8: 인버터·스트링 현장점검 | I8: 구현
A9: CLIPPING | B9: 인버터 클리핑 가능성 | C9: DC/AC 비율 | D9: DC/AC ≥ 1.25 (≥1.35 보통) | E9: 낮음~보통 | F9: DC/AC 설계비율 | G9: 맑은 날 시간별 AC 출력 | H9: 정오 출력 평탄화 확인 | I9: 부분 구현
A10: CURTAIL | B10: 출력제한 손실 | C10: 출력제한률/이벤트 | D10: 출력제한률 > 0 (≥5% 높음) | E10: 보통~높음 | F10: 입력된 제한률 | G10: 계통지시·접속용량·PPA | H10: 이벤트별 손실량 검증 | I10: 구현
A11: AGE | B11: 모듈 경년열화 | C11: 상업운전일, 열화율 | D11: 운영연수 ≥ 5년 | E11: 낮음 | F11: 운영연수와 누적 보정률 | G11: 기상보정 연도별 추세 | H11: 보증 열화율과 실제 추세 비교 | I11: 구현
A12: MISSING | B12: 원인진단 자료 부족 | C12: 데이터 등급 | D12: 등급 C 또는 D | E12: 보통 | F12: 부족한 데이터 목록 | G12: POA/GHI, 인버터, 정지기록 | H12: 추가 계측자료 확보 | I12: 구현
A13: ZERO_GEN | B13: 일사 존재 시 무발전 | C13: 시간/일별 POA와 발전량 | D13: POA 임계값 이상 & 발전량 0 | E13: 높음 | F13: 발생시각과 지속시간 | G13: 계통, 인버터 상태, 통신 | H13: 고장·정전·계량 오류 구분 | I13: 후속
A14: MORNING_PM | B14: 오전/오후 비대칭 | C14: 시간별 출력·POA | D14: 정오 기준 대칭구간 편차 지속 | E14: 보통 | F14: 시간대별 정상화 출력곡선 | G14: 현장 음영, 방위, 센서 | H14: 음영 및 방향 불일치 확인 | I14: 후속
A15: SOILING | B15: 오염 가능성 | C15: PI, 강우/세척 이력 | D15: 강우·세척 후 PI 유의 회복 | E15: 보통 | F15: 전후 성능 변화 | G15: 세척일, 강우량, 사진 | H15: 오염도 점검 및 세척주기 최적화 | I15: 후속
A16: SENSOR_POA | B16: POA 센서 이상 | C16: GHI/POA/태양기하 | D16: POA/GHI 비율이 방향·계절과 불일치 | E16: 보통 | F16: 센서 비율·고정값·결측 | G16: 설치각, 교정일, 청소상태 | H16: 센서 재설치·교정 | I16: 후속

Sheet 07_데이터사전
A1: 입력·출력 데이터 사전
A2: 웹 API와 보고서에서 사용하는 주요 필드입니다. 모든 시계열 값에는 시간대·단위·출처 및 품질 플래그를 함께 관리하는 것이 목표입니다.
A4: ■ 필드 정의
A5: 영역 | B5: 필드명 | C5: 한글명 | D5: 자료형 | E5: 단위 | F5: 필수 모드 | G5: 허용값/예시 | H5: 결측 처리 | I5: 비고
A6: 발전소 | B6: plant_name | C6: 발전소명 | D6: string | E6: - | F6: 전체 | G6: 1MW 태양광발전소 | H6: 기본명 적용
A7: 발전소 | B7: region | C7: 지역권역 | D7: enum | E7: - | F7: 전체 | G7: 서울경기 등 10개 권역 | H7: 필수 | I7: 주소 기반 자동선정 후속
A8: 발전소 | B8: analysis_year | C8: 분석연도 | D8: integer | E8: year | F8: 전체 | G8: 2016~2025 | H8: 필수 | I8: 현재 기준자료 기간
A9: 발전소 | B9: commercial_date | C9: 상업운전일 | D9: date | E9: YYYY-MM-DD | F9: 선택 | G9: 2020-01-01 | H9: 열화 FACTOR=1
A10: 설비 | B10: capacity_dc_kwp | C10: DC 설치용량 | D10: number | E10: kWp | F10: 전체 | G10: 1000 | H10: 필수 | I10: 발전량 정규화 기준
A11: 설비 | B11: capacity_ac_kw | C11: AC 설치용량 | D11: number | E11: kW | F11: 상세 | G11: 900 | H11: DC와 같게 추정 | I11: 클리핑/이용률 산정
A12: 설비 | B12: inverters | C12: 인버터 배열 | D12: array | E12: - | F12: B 이상 | G12: 이름, AC/DC용량, 발전량 | H12: 없음 | I12: 인버터 편차 분석
A13: 설치조건 | B13: tilt_deg | C13: 모듈 경사각 | D13: number | E13: degree | F13: C 이상 | G13: 0~90 | H13: 30° 추정 | I13: 추정값 표시
A14: 설치조건 | B14: azimuth_deg | C14: 모듈 방위각 | D14: number | E14: degree | F14: C 이상 | G14: 북0 동90 남180 서270 | H14: 180° 추정
A15: 설치조건 | B15: latitude | C15: 현장 위도 | D15: number | E15: degree N | F15: 전문가 | G15: 33~38 | H15: 권역 대표위도
A16: 발전량 | B16: actual_monthly_kwh | C16: 월별 실제 발전량 | D16: array[12] | E16: kWh/month | F16: 전체 | G16: 1~12월 | H16: 미입력 월 제외 | I16: 0과 결측을 구분
A17: 일사량 | B17: actual_ghi_monthly | C17: 현장 월별 GHI | D17: array[12] | E17: kWh/m²/month | F17: B 이상 | G17: 1~12월 | H17: 선택연도 지역 GHI
A18: 일사량 | B18: actual_poa_monthly | C18: 현장 월별 POA | D18: array[12] | E18: kWh/m²/month | F18: A/B | G18: 1~12월 | H18: GHI에서 계산 | I18: 현장값 최우선
A19: 계산 | B19: calculation_method | C19: 계산방식 | D19: enum | E19: - | F19: 전체 | G19: pr_based / component_loss_based | H19: pr_based | I19: 항목별 방식은 전문가 권한
A20: 계산 | B20: component_losses | C20: 항목별 FACTOR | D20: object | E20: - | F20: 전문가 | G20: iam, shading 등 | H20: 기본값 | I20: PR과 중복 금지
A21: 출력 | B21: performance_index | C21: 발전성능지수 | D21: number | E21: % | F21: 전체 | G21: Actual / Weather expected | H21: 실적 없으면 null
A22: 출력 | B22: expected_weather_matched_kwh | C22: 입력기간 기상보정 예상량 | D22: number | E22: kWh | F22: 전체 | G22: 실제값이 있는 월만 합산 | H22: 실적 미입력 시 0 | I22: 부분연도 비교 기준
A23: 출력 | B23: actual_month_count | C23: 실적 입력 월수 | D23: integer | E23: month | F23: 전체 | G23: 0~12 | H23: 0 | I23: 자료 범위 표시
A24: 출력 | B24: coverage_pct | C24: 실적 자료 커버리지 | D24: number | E24: % | F24: 전체 | G24: 0~100 | H24: 0 | I24: actual_month_count / 12
A25: 출력 | B25: data_quality.grade | C25: 데이터 등급 | D25: enum | E25: - | F25: 전체 | G25: A/B/C/D | H25: 자동 | I25: 분석범위 제한
A26: 출력 | B26: diagnoses | C26: 저하요인 진단 | D26: array | E26: - | F26: 전체 | G26: 원인, 가능성, 근거, 조치 | H26: 최소 1개 | I26: 고장 확정 금지
A27: 전문가 | B27: expert_evidence | C27: 전문가 첨부자료 | D27: array | E27: PNG/JPG | F27: 전문가 | G27: id, 파일명, 제목, 설명 | H27: 미입력 허용 | I27: PPT/PDF 부록 자동 반영

Sheet 08_검증CASE
A1: 계산 및 진단 검증 CASE
A2: 프로그램 배포 전 동일 입력으로 Excel/코드 결과를 비교합니다. 월별 예상량 허용오차 ±0.1%, 연간 ±0.05%를 기본으로 합니다.
A4: ■ 검증 CASE 목록
A5: CASE ID | B5: 시나리오 | C5: 핵심 입력 | D5: 예상 결과 | E5: 검증 지표 | F5: 허용오차/판정 | G5: 자동화 상태 | H5: 비고
A6: TC-001 | B6: 정상 1MW 남향 30° | C6: 서울경기, 2025, DC 1000, AC 1000, PR 80%, 실제=기상보정 예상 | D6: PI 약 100%, 정상 | E6: 월/연 예상량, PI | F6: 월 ±0.1%, 연 ±0.05% | G6: 수동/코드 | H6: 기본 회귀테스트
A7: TC-002 | B7: 실제 발전량 미입력 | C7: TC-001과 동일, 실제 12개월 공란 | D7: '실적 입력 필요' 반환 | E7: 판정, null 처리 | F7: 오류 없음 | G7: 코드
A8: TC-003 | B8: 일사량이 장기평균보다 낮은 연도 | C8: 지역 연도 GHI 비율 < 96% | D8: 기상요인 진단 | E8: weather_ratio, 진단코드 | F8: 임계값 정확 일치 | G8: 코드
A9: TC-004 | B9: 기상보정 후 10% 저하 | C9: 실제 = 기상보정 예상 × 0.90 | D9: 관찰 또는 주의, PERF_LOW | E9: PI, 판정, 진단 | F9: 임계값 일치 | G9: 코드
A10: TC-005 | B10: 특정 인버터 10% 저하 | C10: 2대 동일 DC, 한 대 kWh/kWp -10% | D10: INV_LOW 보통 | E10: 중앙값 편차 | F10: ±0.1%p | G10: 코드
A11: TC-006 | B11: DC/AC 1.35 | C11: DC 1000, AC 740 | D11: 클리핑 가능성 보통 | E11: 비율, 진단 | F11: 조건 경계 확인 | G11: 코드 | H11: 시간자료 없으므로 확정 금지
A12: TC-007 | B12: 출력제한 5% | C12: curtailment_rate = 0.05 | D12: 예상량 5% 감소, CURTAIL 높음 | E12: 발전량, 진단 | F12: ±0.01% | G12: 코드
A13: TC-008 | B13: 상업운전 10년 | C13: 연 열화율 0.5%, 운영 10년 | D13: F_age 약 0.951 | E13: 열화 FACTOR | F13: ±0.001 | G13: 코드
A14: TC-009 | B14: 현장 POA 우선 | C14: POA 12개월 입력, GHI도 입력 | D14: 기상예상량은 POA 직접 적용 | E14: weather_source, 예상량 | F14: POA 우선 | G14: 코드
A15: TC-010 | B15: 항목별 손실 권한 | C15: 전문가 토큰 없이 component 요청 | D15: PR 방식으로 강제 | E15: calculation_method | F15: 권한 차단 | G15: 코드
A16: TC-011 | B16: 결측 월 | C16: 실제 6개월만 입력 | D16: 해당 6개월 예상량 합으로 PI 계산 | E16: annual actual_month_count | F16: 6 | G16: 코드 | H16: 부분연도 문구 및 동일기간 예상량 확인
A17: TC-012 | B17: 단위 오류 파일 | C17: 발전량 컬럼에 문자열/음수 포함 | D17: 유효행만 집계, 음수 제외 | E17: rows_valid, 월합계 | F17: 오류 메시지 명확 | G17: 코드
A18: TC-013 | B18: 업로드 결측월 | C18: 1월·3월만 있는 CSV | D18: 2월 등 결측월은 null, 0으로 대체하지 않음 | E18: 업로드 monthly array | F18: null 유지 | G18: 코드 | H18: 데이터품질 경고 표시
A19: TC-014 | B19: 로컬 프로젝트 저장 | C19: 입력값·분석결과 저장 후 재조회 | D19: 동일 입력·결과 복원 | E19: SQLite CRUD | F19: 일치 | G19: 코드 | H19: 외부 전송 없음
A20: TC-015 | B20: 전문가 이미지 부록 | C20: 전문가 토큰 + PNG/JPG 첨부 | D20: PPT/PDF에 제목·설명과 이미지 포함 | E20: 보고서 페이지/슬라이드 | F20: 오버플로 없음 | G20: 코드 | H20: 전문가 권한 필요
A22: ※ 구버전 자료에서 TC-012 가 두 건 중복되어 있어 v1.0에서 일련번호를 다시 부여했습니다(총 15건).

Sheet 09_보고서구성
A1: 보고서 구성
A2: PDF는 공식 보관용, PPT는 고객 설명·전문가 편집용, Excel은 계산검증·기술분석용으로 역할을 분리합니다.
A4: ■ 산출물별 구성
A5: 산출물 | B5: 섹션/슬라이드 | C5: 자동 생성내용 | D5: 전문가 추가내용 | E5: 고객 공개 | F5: MVP 구현 | G5: 후속 기능
A6: 고객 PDF | B6: 표지/분석조건 | C6: 발전소, 분석연도, 용량, 모델버전 | D6: 승인자/기관정보 | E6: 예 | F6: 구현 | G6: 전자서명·승인
A7: 고객 PDF | B7: 종합판정/KPI | C7: 실제·장기·기상보정 예상, PI, 데이터등급 | D7: 전문가 요약 의견 | E7: 예 | F7: 구현 | G7: 브랜드 템플릿
A8: 고객 PDF | B8: 월별 비교 | C8: 월별 실제·예상 표 | D8: 특이월 주석 | E8: 예 | F8: 구현 | G8: 그래프 이미지 강화
A9: 고객 PDF | B9: 저하요인/권장조치 | C9: 가능성, 근거, 권장조치 | D9: 현장확인 결과 | E9: 예 | F9: 구현(전문가 이미지 부록 포함) | G9: 사진 첨부
A10: 고객 PPT | B10: 표지/종합판정 | C10: 고객 발표용 핵심 결과 | D10: 설명 순서 수정 | E10: 예 | F10: 구현 | G10: 슬라이드 선택
A11: 고객 PPT | B11: 월별 발전량 차트 | C11: 기상보정 예상과 실제 | D11: 특이월 강조 | E11: 예 | F11: 구현 | G11: 회사 테마
A12: 고객 PPT | B12: 전문가 검토의견 | C12: 입력한 전문가 의견 | D12: 현장사진, 열화상, 알람, IV Curve | E12: 예 | F12: 구현(이미지 업로드 포함) | G12: 슬라이드 순서·선택·회사 테마
A13: 상세 Excel | B13: 분석요약/월별 | C13: 수치와 수식, 차트 | D13: 검토 의견 | E13: 전문가 | F13: 구현 | G13: 원본데이터 포함
A14: 상세 Excel | B14: 계산식/FACTOR | C14: 계산변수, 손실계수, 데이터품질 | D14: 관리자 승인값 | E14: 전문가 | F14: 구현 | G14: 버전 스냅샷

Sheet 10_개발연계
A1: 웹 프로그램 개발 연계
A2: 현재 MVP 코드와 본 워크북을 같은 입력으로 비교하고, 변경 시 모델 버전과 변경이력을 함께 갱신합니다.
A4: ■ 컴포넌트별 연계
A5: 구분 | B5: 경로/컴포넌트 | C5: 역할 | D5: 현재 버전 | E5: 검증방법 | F5: 보안/운영 주의 | G5: 후속
A6: 백엔드 | B6: app.py + solar_core.py | C6: API·권한·업로드 및 POA/예상량/PI/진단 계산 | D6: MVP-0.2.0 | E6: pytest/API 회귀테스트 | F6: 전문가 PIN·토큰 비밀값은 배포 전 변경 | G6: RBAC/사용자 인증
A7: 프런트엔드 | B7: static/index.html, app.js | C7: 간편·상세·전문가 입력, 프로젝트 저장, 결과표시 | D7: MVP-0.2.0 | E7: 브라우저 입력/다운로드 테스트 | F7: 전문가 기능은 서버 토큰 검증 | G7: Next.js 전환
A8: 기준 데이터 | B8: data/solar_data.json | C8: 2016~2025 10개 권역 월별 GHI | D8: 2016-2025 | E8: 원자료 1,200행 대조 | F8: 출처·기간·버전 보관 | G8: 기상 API 자동갱신
A9: 고객 PDF | B9: /api/report/pdf + reports.py | C9: 공식 고객 보고서 및 전문가 이미지 부록 | D9: MVP-0.2.0 | E9: PDF 렌더링 검토 | F9: 면책·모델버전 포함 | G9: 승인 워크플로
A10: 고객 PPT | B10: /api/report/pptx + PptxGenJS | C10: 고객 설명 및 전문가 첨부자료 슬라이드 | D10: MVP-0.2.0 | E10: 슬라이드 렌더·오버플로 검사 | F10: 자동결과와 전문가 의견 구분 | G10: 브랜드 템플릿
A11: 상세 Excel | B11: /api/report/excel + reports.py | C11: 월별 결과, FACTOR, 계산식, 데이터품질 | D11: MVP-0.2.0 | E11: LibreOffice 재계산·수식 오류 검사 | F11: 동적배열 함수 사용 금지 | G11: 원본자료 상세
A12: 전문가 권한 | B12: /api/expert/unlock | C12: 만료시간이 있는 서명 토큰 발급 | D12: MVP-0.2.0 | E12: 잘못된 PIN 401, 만료/변조 토큰 확인 | F12: 초기 PIN은 데모 전용이므로 배포 전 반드시 변경 | G12: RBAC/OAuth
A13: 모델 변경 | B13: MODEL_VERSION | C13: 보고서·결과 JSON·PPT/Excel에 기록 | D13: MVP-0.2.0 | E13: 코드·Excel 버전 일치 확인 | F13: 분석 실행 시 입력·결과 스냅샷 | G13: 모델 레지스트리
A14: 로컬 저장 | B14: storage.py / SQLite | C14: 프로젝트 입력값·분석결과 저장·불러오기 | D14: MVP-0.2.0 | E14: CRUD API 테스트 | F14: PC 로컬 파일 권한·백업 필요 | G14: 다중 사용자 DB
A15: 전문가 첨부 | B15: /api/evidence/* | C15: 현장사진·열화상·알람 이미지 로컬 저장 | D15: MVP-0.2.0 | E15: 권한·용량·확장자 테스트 | F15: PNG/JPG, 10MB 제한 | G15: 문서/IV Curve 파일 지원

Sheet 11_발전량_모델
A1: 경사면 일사량 및 발전량 계산 모델
A2: 지역별 월 수평면 일사량을 직달·산란으로 분리하고, 경사각·방위각·지면반사를 반영한 POA와 발전량을 계산합니다.
A4: ① 분석 입력 | E4: ② 주요 결과 | I4: ③ 계산 절차 및 주의사항
A5: 분석 지역 | B5: 서울경기 | C5: 광역권 10개 중 선택 | E5: 연간 수평면 일사량 | F5: =SUM(C22:C33) | G5: kWh/m²/년 | I5: ① 월 수평면 일사량(원자료)을 월 일평균 H로 환산합니다.
A6: 분석 기준 | B6: 10년평균 | C6: 10년평균 또는 개별연도(2016~2025) | E6: 연간 경사면 일사량 POA | F6: =SUM(P22:P33) | G6: kWh/m²/년 | I6: ② 대기권외 일사량 H0와 청명도지수 Kt = H/H0 를 계산합니다.
A7: 경사각 β (°) | B7: 30 | C7: 0° = 수평, 90° = 수직 | E7: 경사면/수평면 FACTOR | F7: =IF(F5=0,0,F6/F5) | G7: 배 | I7: ③ Erbs 월평균 상관식으로 산란 성분 Hd 를 추정합니다.
A8: 방위각 A (°) | B8: 180 | C8: 0° 북 / 90° 동 / 180° 남 / 270° 서 | E8: 연간 특성발전량 | F8: =SUM(R22:R33) | G8: kWh/kWp | I8: ④ 15분 태양기하 적분으로 방위·경사 직달계수 Rb 를 계산합니다.
A9: 지면반사율 ρg | B9: 0.2 | C9: 일반 토지 기본 0.20 (기본값 출처: 05_FACTOR_기준값) | E9: 연간 발전량 | F9: =SUM(S22:S33) | G9: MWh/년 | I9: ⑤ POA = Hb×Rb + Hd×(1+cosβ)/2 + H×ρg×(1-cosβ)/2
A10: DC 설비용량 (kWp) | B10: 1000 | C10: 발전량·특성발전량 환산 기준 | E10: 설비이용률 | F10: =IF(B10=0,0,F9/(B10*8.76)) | G10: % | I10: ⑥ 발전량 = POA × DC용량 × PR × 가동률 × (1-출력제한) × 기타계수
A11: 기준 PR | B11: 0.8 | C11: 온도·인버터·배선·오염 등 종합손실 포함 | E11: 경사면 증가율 | F11: =IF(F5=0,0,F6/F5-1) | G11: %
A12: 가동률 | B12: 0.995 | C12: 고장·정비로 발전 불가능한 시간 반영 | E12: 검토 상태 | F12: =IF(COUNTIF(T22:T33,"<>정상")=0,"정상","검토 필요") | G12: - | I12: ※ 광역권 월자료 기반의 예비·타당성 분석용입니다.
A13: 출력제한/계통손실률 | B13: 0 | C13: 의도적 감발(고장·정비 제외) | I13: ※ 금융·성능보증용은 현장 좌표, 시간별 DNI/DHI, 음영, 온도, 출력제한 자료를 적용하세요.
A14: 기타 보정계수 | B14: 1 | C14: 프로젝트 특수보정 (PR과 중복 금지) | I14: ※ 노란 배경·파란 글씨 셀만 입력값이며, 상세 한계는 '16_적용한계·참고' 시트를 참고하세요.
A15: 지역 대표 위도 (°N) | B15: =INDEX('14_지역·상수'!$C$5:$C$14,MATCH(B5,'14_지역·상수'!$A$5:$A$14,0)) | C15: 선택 지역의 대표 도시 위도(자동)
A16: 현장 위도 수동입력 (선택) | C16: 실제 발전소 위도를 알면 입력(권장)
A17: 적용 위도 φ (°N) | B17: =IF(B16="",B15,B16) | C17: 수동입력이 있으면 우선 적용
A20: ④ 월별 계산 결과 (1~12월)
A21: 월 | B21: 일수 [일] | C21: 수평면 월일사량 [kWh/m²] | D21: 수평면 일평균 H [kWh/m²/일] | E21: 대기권외 H0 [kWh/m²/일] | F21: Kt | G21: Kt 적용값 | H21: 산란비 Hd/H | I21: 산란 H_d [kWh/m²/일] | J21: 직달 H_b [kWh/m²/일] | K21: Rb | L21: 직달 POA [kWh/m²/일] | M21: 천공산란 POA [kWh/m²/일] | N21: 지면반사 POA [kWh/m²/일] | O21: POA 일평균 [kWh/m²/일] | P21: POA 월일사량 [kWh/m²] | Q21: POA FACTOR [배] | R21: 특성발전량 [kWh/kWp] | S21: 발전량 [MWh] | T21: 검토
A22: 1 | B22: =IF($B$6="10년평균",AVERAGEIFS(RawDataKWh[일수],RawDataKWh[월],$A22,RawDataKWh[지역명],$B$5),SUMIFS(RawDataKWh[일수],RawDataKWh[월],$A22,RawDataKWh[연도],VALUE($B$6),RawDataKWh[지역명],$B$5)) | C22: =IF($B$6="10년평균",AVERAGEIFS(RawDataKWh[일사합_kWh_m2],RawDataKWh[월],$A22,RawDataKWh[지역명],$B$5),SUMIFS(RawDataKWh[일사합_kWh_m2],RawDataKWh[월],$A22,RawDataKWh[연도],VALUE($B$6),RawDataKWh[지역명],$B$5)) | D22: =IF(B22=0,0,C22/B22) | E22: =INDEX('15_태양기하'!$H$4:$H$15,MATCH(A22,'15_태양기하'!$A$4:$A$15,0)) | F22: =IF(E22=0,0,D22/E22) | G22: =MAX('14_지역·상수'!$H$7,MIN('14_지역·상수'!$H$8,F22)) | H22: =MAX(0.05,MIN(1,IF(INDEX('15_태양기하'!$D$4:$D$15,MATCH(A22,'15_태양기하'!$A$4:$A$15,0))<=81.4,1.391-3.56*G22+4.189*G22^2-2.137*G22^3,1.311-3.022*G22+3.427*G22^2-1.821*G22^3))) | I22: =D22*H22 | J22: =D22-I22 | K22: =INDEX('15_태양기하'!$G$4:$G$15,MATCH(A22,'15_태양기하'!$A$4:$A$15,0)) | L22: =J22*K22 | M22: =I22*(1+COS(RADIANS($B$7)))/2 | N22: =D22*$B$9*(1-COS(RADIANS($B$7)))/2 | O22: =L22+M22+N22 | P22: =O22*B22 | Q22: =IF(C22=0,0,P22/C22) | R22: =P22*$B$11*$B$12*(1-$B$13)*$B$14 | S22: =R22*$B$10/1000 | T22: =IF(OR(F22<'14_지역·상수'!$H$7,F22>'14_지역·상수'!$H$8),"Kt 범위 검토",IF(OR(K22<0,K22>5),"Rb 검토","정상"))
A23: 2 | B23: =IF($B$6="10년평균",AVERAGEIFS(RawDataKWh[일수],RawDataKWh[월],$A23,RawDataKWh[지역명],$B$5),SUMIFS(RawDataKWh[일수],RawDataKWh[월],$A23,RawDataKWh[연도],VALUE($B$6),RawDataKWh[지역명],$B$5)) | C23: =IF($B$6="10년평균",AVERAGEIFS(RawDataKWh[일사합_kWh_m2],RawDataKWh[월],$A23,RawDataKWh[지역명],$B$5),SUMIFS(RawDataKWh[일사합_kWh_m2],RawDataKWh[월],$A23,RawDataKWh[연도],VALUE($B$6),RawDataKWh[지역명],$B$5)) | D23: =IF(B23=0,0,C23/B23) | E23: =INDEX('15_태양기하'!$H$4:$H$15,MATCH(A23,'15_태양기하'!$A$4:$A$15,0)) | F23: =IF(E23=0,0,D23/E23) | G23: =MAX('14_지역·상수'!$H$7,MIN('14_지역·상수'!$H$8,F23)) | H23: =MAX(0.05,MIN(1,IF(INDEX('15_태양기하'!$D$4:$D$15,MATCH(A23,'15_태양기하'!$A$4:$A$15,0))<=81.4,1.391-3.56*G23+4.189*G23^2-2.137*G23^3,1.311-3.022*G23+3.427*G23^2-1.821*G23^3))) | I23: =D23*H23 | J23: =D23-I23 | K23: =INDEX('15_태양기하'!$G$4:$G$15,MATCH(A23,'15_태양기하'!$A$4:$A$15,0)) | L23: =J23*K23 | M23: =I23*(1+COS(RADIANS($B$7)))/2 | N23: =D23*$B$9*(1-COS(RADIANS($B$7)))/2 | O23: =L23+M23+N23 | P23: =O23*B23 | Q23: =IF(C23=0,0,P23/C23) | R23: =P23*$B$11*$B$12*(1-$B$13)*$B$14 | S23: =R23*$B$10/1000 | T23: =IF(OR(F23<'14_지역·상수'!$H$7,F23>'14_지역·상수'!$H$8),"Kt 범위 검토",IF(OR(K23<0,K23>5),"Rb 검토","정상"))
A24: 3 | B24: =IF($B$6="10년평균",AVERAGEIFS(RawDataKWh[일수],RawDataKWh[월],$A24,RawDataKWh[지역명],$B$5),SUMIFS(RawDataKWh[일수],RawDataKWh[월],$A24,RawDataKWh[연도],VALUE($B$6),RawDataKWh[지역명],$B$5)) | C24: =IF($B$6="10년평균",AVERAGEIFS(RawDataKWh[일사합_kWh_m2],RawDataKWh[월],$A24,RawDataKWh[지역명],$B$5),SUMIFS(RawDataKWh[일사합_kWh_m2],RawDataKWh[월],$A24,RawDataKWh[연도],VALUE($B$6),RawDataKWh[지역명],$B$5)) | D24: =IF(B24=0,0,C24/B24) | E24: =INDEX('15_태양기하'!$H$4:$H$15,MATCH(A24,'15_태양기하'!$A$4:$A$15,0)) | F24: =IF(E24=0,0,D24/E24) | G24: =MAX('14_지역·상수'!$H$7,MIN('14_지역·상수'!$H$8,F24)) | H24: =MAX(0.05,MIN(1,IF(INDEX('15_태양기하'!$D$4:$D$15,MATCH(A24,'15_태양기하'!$A$4:$A$15,0))<=81.4,1.391-3.56*G24+4.189*G24^2-2.137*G24^3,1.311-3.022*G24+3.427*G24^2-1.821*G24^3))) | I24: =D24*H24 | J24: =D24-I24 | K24: =INDEX('15_태양기하'!$G$4:$G$15,MATCH(A24,'15_태양기하'!$A$4:$A$15,0)) | L24: =J24*K24 | M24: =I24*(1+COS(RADIANS($B$7)))/2 | N24: =D24*$B$9*(1-COS(RADIANS($B$7)))/2 | O24: =L24+M24+N24 | P24: =O24*B24 | Q24: =IF(C24=0,0,P24/C24) | R24: =P24*$B$11*$B$12*(1-$B$13)*$B$14 | S24: =R24*$B$10/1000 | T24: =IF(OR(F24<'14_지역·상수'!$H$7,F24>'14_지역·상수'!$H$8),"Kt 범위 검토",IF(OR(K24<0,K24>5),"Rb 검토","정상"))
A25: 4 | B25: =IF($B$6="10년평균",AVERAGEIFS(RawDataKWh[일수],RawDataKWh[월],$A25,RawDataKWh[지역명],$B$5),SUMIFS(RawDataKWh[일수],RawDataKWh[월],$A25,RawDataKWh[연도],VALUE($B$6),RawDataKWh[지역명],$B$5)) | C25: =IF($B$6="10년평균",AVERAGEIFS(RawDataKWh[일사합_kWh_m2],RawDataKWh[월],$A25,RawDataKWh[지역명],$B$5),SUMIFS(RawDataKWh[일사합_kWh_m2],RawDataKWh[월],$A25,RawDataKWh[연도],VALUE($B$6),RawDataKWh[지역명],$B$5)) | D25: =IF(B25=0,0,C25/B25) | E25: =INDEX('15_태양기하'!$H$4:$H$15,MATCH(A25,'15_태양기하'!$A$4:$A$15,0)) | F25: =IF(E25=0,0,D25/E25) | G25: =MAX('14_지역·상수'!$H$7,MIN('14_지역·상수'!$H$8,F25)) | H25: =MAX(0.05,MIN(1,IF(INDEX('15_태양기하'!$D$4:$D$15,MATCH(A25,'15_태양기하'!$A$4:$A$15,0))<=81.4,1.391-3.56*G25+4.189*G25^2-2.137*G25^3,1.311-3.022*G25+3.427*G25^2-1.821*G25^3))) | I25: =D25*H25 | J25: =D25-I25 | K25: =INDEX('15_태양기하'!$G$4:$G$15,MATCH(A25,'15_태양기하'!$A$4:$A$15,0)) | L25: =J25*K25 | M25: =I25*(1+COS(RADIANS($B$7)))/2 | N25: =D25*$B$9*(1-COS(RADIANS($B$7)))/2 | O25: =L25+M25+N25 | P25: =O25*B25 | Q25: =IF(C25=0,0,P25/C25) | R25: =P25*$B$11*$B$12*(1-$B$13)*$B$14 | S25: =R25*$B$10/1000 | T25: =IF(OR(F25<'14_지역·상수'!$H$7,F25>'14_지역·상수'!$H$8),"Kt 범위 검토",IF(OR(K25<0,K25>5),"Rb 검토","정상"))
A26: 5 | B26: =IF($B$6="10년평균",AVERAGEIFS(RawDataKWh[일수],RawDataKWh[월],$A26,RawDataKWh[지역명],$B$5),SUMIFS(RawDataKWh[일수],RawDataKWh[월],$A26,RawDataKWh[연도],VALUE($B$6),RawDataKWh[지역명],$B$5)) | C26: =IF($B$6="10년평균",AVERAGEIFS(RawDataKWh[일사합_kWh_m2],RawDataKWh[월],$A26,RawDataKWh[지역명],$B$5),SUMIFS(RawDataKWh[일사합_kWh_m2],RawDataKWh[월],$A26,RawDataKWh[연도],VALUE($B$6),RawDataKWh[지역명],$B$5)) | D26: =IF(B26=0,0,C26/B26) | E26: =INDEX('15_태양기하'!$H$4:$H$15,MATCH(A26,'15_태양기하'!$A$4:$A$15,0)) | F26: =IF(E26=0,0,D26/E26) | G26: =MAX('14_지역·상수'!$H$7,MIN('14_지역·상수'!$H$8,F26)) | H26: =MAX(0.05,MIN(1,IF(INDEX('15_태양기하'!$D$4:$D$15,MATCH(A26,'15_태양기하'!$A$4:$A$15,0))<=81.4,1.391-3.56*G26+4.189*G26^2-2.137*G26^3,1.311-3.022*G26+3.427*G26^2-1.821*G26^3))) | I26: =D26*H26 | J26: =D26-I26 | K26: =INDEX('15_태양기하'!$G$4:$G$15,MATCH(A26,'15_태양기하'!$A$4:$A$15,0)) | L26: =J26*K26 | M26: =I26*(1+COS(RADIANS($B$7)))/2 | N26: =D26*$B$9*(1-COS(RADIANS($B$7)))/2 | O26: =L26+M26+N26 | P26: =O26*B26 | Q26: =IF(C26=0,0,P26/C26) | R26: =P26*$B$11*$B$12*(1-$B$13)*$B$14 | S26: =R26*$B$10/1000 | T26: =IF(OR(F26<'14_지역·상수'!$H$7,F26>'14_지역·상수'!$H$8),"Kt 범위 검토",IF(OR(K26<0,K26>5),"Rb 검토","정상"))
A27: 6 | B27: =IF($B$6="10년평균",AVERAGEIFS(RawDataKWh[일수],RawDataKWh[월],$A27,RawDataKWh[지역명],$B$5),SUMIFS(RawDataKWh[일수],RawDataKWh[월],$A27,RawDataKWh[연도],VALUE($B$6),RawDataKWh[지역명],$B$5)) | C27: =IF($B$6="10년평균",AVERAGEIFS(RawDataKWh[일사합_kWh_m2],RawDataKWh[월],$A27,RawDataKWh[지역명],$B$5),SUMIFS(RawDataKWh[일사합_kWh_m2],RawDataKWh[월],$A27,RawDataKWh[연도],VALUE($B$6),RawDataKWh[지역명],$B$5)) | D27: =IF(B27=0,0,C27/B27) | E27: =INDEX('15_태양기하'!$H$4:$H$15,MATCH(A27,'15_태양기하'!$A$4:$A$15,0)) | F27: =IF(E27=0,0,D27/E27) | G27: =MAX('14_지역·상수'!$H$7,MIN('14_지역·상수'!$H$8,F27)) | H27: =MAX(0.05,MIN(1,IF(INDEX('15_태양기하'!$D$4:$D$15,MATCH(A27,'15_태양기하'!$A$4:$A$15,0))<=81.4,1.391-3.56*G27+4.189*G27^2-2.137*G27^3,1.311-3.022*G27+3.427*G27^2-1.821*G27^3))) | I27: =D27*H27 | J27: =D27-I27 | K27: =INDEX('15_태양기하'!$G$4:$G$15,MATCH(A27,'15_태양기하'!$A$4:$A$15,0)) | L27: =J27*K27 | M27: =I27*(1+COS(RADIANS($B$7)))/2 | N27: =D27*$B$9*(1-COS(RADIANS($B$7)))/2 | O27: =L27+M27+N27 | P27: =O27*B27 | Q27: =IF(C27=0,0,P27/C27) | R27: =P27*$B$11*$B$12*(1-$B$13)*$B$14 | S27: =R27*$B$10/1000 | T27: =IF(OR(F27<'14_지역·상수'!$H$7,F27>'14_지역·상수'!$H$8),"Kt 범위 검토",IF(OR(K27<0,K27>5),"Rb 검토","정상"))
A28: 7 | B28: =IF($B$6="10년평균",AVERAGEIFS(RawDataKWh[일수],RawDataKWh[월],$A28,RawDataKWh[지역명],$B$5),SUMIFS(RawDataKWh[일수],RawDataKWh[월],$A28,RawDataKWh[연도],VALUE($B$6),RawDataKWh[지역명],$B$5)) | C28: =IF($B$6="10년평균",AVERAGEIFS(RawDataKWh[일사합_kWh_m2],RawDataKWh[월],$A28,RawDataKWh[지역명],$B$5),SUMIFS(RawDataKWh[일사합_kWh_m2],RawDataKWh[월],$A28,RawDataKWh[연도],VALUE($B$6),RawDataKWh[지역명],$B$5)) | D28: =IF(B28=0,0,C28/B28) | E28: =INDEX('15_태양기하'!$H$4:$H$15,MATCH(A28,'15_태양기하'!$A$4:$A$15,0)) | F28: =IF(E28=0,0,D28/E28) | G28: =MAX('14_지역·상수'!$H$7,MIN('14_지역·상수'!$H$8,F28)) | H28: =MAX(0.05,MIN(1,IF(INDEX('15_태양기하'!$D$4:$D$15,MATCH(A28,'15_태양기하'!$A$4:$A$15,0))<=81.4,1.391-3.56*G28+4.189*G28^2-2.137*G28^3,1.311-3.022*G28+3.427*G28^2-1.821*G28^3))) | I28: =D28*H28 | J28: =D28-I28 | K28: =INDEX('15_태양기하'!$G$4:$G$15,MATCH(A28,'15_태양기하'!$A$4:$A$15,0)) | L28: =J28*K28 | M28: =I28*(1+COS(RADIANS($B$7)))/2 | N28: =D28*$B$9*(1-COS(RADIANS($B$7)))/2 | O28: =L28+M28+N28 | P28: =O28*B28 | Q28: =IF(C28=0,0,P28/C28) | R28: =P28*$B$11*$B$12*(1-$B$13)*$B$14 | S28: =R28*$B$10/1000 | T28: =IF(OR(F28<'14_지역·상수'!$H$7,F28>'14_지역·상수'!$H$8),"Kt 범위 검토",IF(OR(K28<0,K28>5),"Rb 검토","정상"))
A29: 8 | B29: =IF($B$6="10년평균",AVERAGEIFS(RawDataKWh[일수],RawDataKWh[월],$A29,RawDataKWh[지역명],$B$5),SUMIFS(RawDataKWh[일수],RawDataKWh[월],$A29,RawDataKWh[연도],VALUE($B$6),RawDataKWh[지역명],$B$5)) | C29: =IF($B$6="10년평균",AVERAGEIFS(RawDataKWh[일사합_kWh_m2],RawDataKWh[월],$A29,RawDataKWh[지역명],$B$5),SUMIFS(RawDataKWh[일사합_kWh_m2],RawDataKWh[월],$A29,RawDataKWh[연도],VALUE($B$6),RawDataKWh[지역명],$B$5)) | D29: =IF(B29=0,0,C29/B29) | E29: =INDEX('15_태양기하'!$H$4:$H$15,MATCH(A29,'15_태양기하'!$A$4:$A$15,0)) | F29: =IF(E29=0,0,D29/E29) | G29: =MAX('14_지역·상수'!$H$7,MIN('14_지역·상수'!$H$8,F29)) | H29: =MAX(0.05,MIN(1,IF(INDEX('15_태양기하'!$D$4:$D$15,MATCH(A29,'15_태양기하'!$A$4:$A$15,0))<=81.4,1.391-3.56*G29+4.189*G29^2-2.137*G29^3,1.311-3.022*G29+3.427*G29^2-1.821*G29^3))) | I29: =D29*H29 | J29: =D29-I29 | K29: =INDEX('15_태양기하'!$G$4:$G$15,MATCH(A29,'15_태양기하'!$A$4:$A$15,0)) | L29: =J29*K29 | M29: =I29*(1+COS(RADIANS($B$7)))/2 | N29: =D29*$B$9*(1-COS(RADIANS($B$7)))/2 | O29: =L29+M29+N29 | P29: =O29*B29 | Q29: =IF(C29=0,0,P29/C29) | R29: =P29*$B$11*$B$12*(1-$B$13)*$B$14 | S29: =R29*$B$10/1000 | T29: =IF(OR(F29<'14_지역·상수'!$H$7,F29>'14_지역·상수'!$H$8),"Kt 범위 검토",IF(OR(K29<0,K29>5),"Rb 검토","정상"))
A30: 9 | B30: =IF($B$6="10년평균",AVERAGEIFS(RawDataKWh[일수],RawDataKWh[월],$A30,RawDataKWh[지역명],$B$5),SUMIFS(RawDataKWh[일수],RawDataKWh[월],$A30,RawDataKWh[연도],VALUE($B$6),RawDataKWh[지역명],$B$5)) | C30: =IF($B$6="10년평균",AVERAGEIFS(RawDataKWh[일사합_kWh_m2],RawDataKWh[월],$A30,RawDataKWh[지역명],$B$5),SUMIFS(RawDataKWh[일사합_kWh_m2],RawDataKWh[월],$A30,RawDataKWh[연도],VALUE($B$6),RawDataKWh[지역명],$B$5)) | D30: =IF(B30=0,0,C30/B30) | E30: =INDEX('15_태양기하'!$H$4:$H$15,MATCH(A30,'15_태양기하'!$A$4:$A$15,0)) | F30: =IF(E30=0,0,D30/E30) | G30: =MAX('14_지역·상수'!$H$7,MIN('14_지역·상수'!$H$8,F30)) | H30: =MAX(0.05,MIN(1,IF(INDEX('15_태양기하'!$D$4:$D$15,MATCH(A30,'15_태양기하'!$A$4:$A$15,0))<=81.4,1.391-3.56*G30+4.189*G30^2-2.137*G30^3,1.311-3.022*G30+3.427*G30^2-1.821*G30^3))) | I30: =D30*H30 | J30: =D30-I30 | K30: =INDEX('15_태양기하'!$G$4:$G$15,MATCH(A30,'15_태양기하'!$A$4:$A$15,0)) | L30: =J30*K30 | M30: =I30*(1+COS(RADIANS($B$7)))/2 | N30: =D30*$B$9*(1-COS(RADIANS($B$7)))/2 | O30: =L30+M30+N30 | P30: =O30*B30 | Q30: =IF(C30=0,0,P30/C30) | R30: =P30*$B$11*$B$12*(1-$B$13)*$B$14 | S30: =R30*$B$10/1000 | T30: =IF(OR(F30<'14_지역·상수'!$H$7,F30>'14_지역·상수'!$H$8),"Kt 범위 검토",IF(OR(K30<0,K30>5),"Rb 검토","정상"))
A31: 10 | B31: =IF($B$6="10년평균",AVERAGEIFS(RawDataKWh[일수],RawDataKWh[월],$A31,RawDataKWh[지역명],$B$5),SUMIFS(RawDataKWh[일수],RawDataKWh[월],$A31,RawDataKWh[연도],VALUE($B$6),RawDataKWh[지역명],$B$5)) | C31: =IF($B$6="10년평균",AVERAGEIFS(RawDataKWh[일사합_kWh_m2],RawDataKWh[월],$A31,RawDataKWh[지역명],$B$5),SUMIFS(RawDataKWh[일사합_kWh_m2],RawDataKWh[월],$A31,RawDataKWh[연도],VALUE($B$6),RawDataKWh[지역명],$B$5)) | D31: =IF(B31=0,0,C31/B31) | E31: =INDEX('15_태양기하'!$H$4:$H$15,MATCH(A31,'15_태양기하'!$A$4:$A$15,0)) | F31: =IF(E31=0,0,D31/E31) | G31: =MAX('14_지역·상수'!$H$7,MIN('14_지역·상수'!$H$8,F31)) | H31: =MAX(0.05,MIN(1,IF(INDEX('15_태양기하'!$D$4:$D$15,MATCH(A31,'15_태양기하'!$A$4:$A$15,0))<=81.4,1.391-3.56*G31+4.189*G31^2-2.137*G31^3,1.311-3.022*G31+3.427*G31^2-1.821*G31^3))) | I31: =D31*H31 | J31: =D31-I31 | K31: =INDEX('15_태양기하'!$G$4:$G$15,MATCH(A31,'15_태양기하'!$A$4:$A$15,0)) | L31: =J31*K31 | M31: =I31*(1+COS(RADIANS($B$7)))/2 | N31: =D31*$B$9*(1-COS(RADIANS($B$7)))/2 | O31: =L31+M31+N31 | P31: =O31*B31 | Q31: =IF(C31=0,0,P31/C31) | R31: =P31*$B$11*$B$12*(1-$B$13)*$B$14 | S31: =R31*$B$10/1000 | T31: =IF(OR(F31<'14_지역·상수'!$H$7,F31>'14_지역·상수'!$H$8),"Kt 범위 검토",IF(OR(K31<0,K31>5),"Rb 검토","정상"))
A32: 11 | B32: =IF($B$6="10년평균",AVERAGEIFS(RawDataKWh[일수],RawDataKWh[월],$A32,RawDataKWh[지역명],$B$5),SUMIFS(RawDataKWh[일수],RawDataKWh[월],$A32,RawDataKWh[연도],VALUE($B$6),RawDataKWh[지역명],$B$5)) | C32: =IF($B$6="10년평균",AVERAGEIFS(RawDataKWh[일사합_kWh_m2],RawDataKWh[월],$A32,RawDataKWh[지역명],$B$5),SUMIFS(RawDataKWh[일사합_kWh_m2],RawDataKWh[월],$A32,RawDataKWh[연도],VALUE($B$6),RawDataKWh[지역명],$B$5)) | D32: =IF(B32=0,0,C32/B32) | E32: =INDEX('15_태양기하'!$H$4:$H$15,MATCH(A32,'15_태양기하'!$A$4:$A$15,0)) | F32: =IF(E32=0,0,D32/E32) | G32: =MAX('14_지역·상수'!$H$7,MIN('14_지역·상수'!$H$8,F32)) | H32: =MAX(0.05,MIN(1,IF(INDEX('15_태양기하'!$D$4:$D$15,MATCH(A32,'15_태양기하'!$A$4:$A$15,0))<=81.4,1.391-3.56*G32+4.189*G32^2-2.137*G32^3,1.311-3.022*G32+3.427*G32^2-1.821*G32^3))) | I32: =D32*H32 | J32: =D32-I32 | K32: =INDEX('15_태양기하'!$G$4:$G$15,MATCH(A32,'15_태양기하'!$A$4:$A$15,0)) | L32: =J32*K32 | M32: =I32*(1+COS(RADIANS($B$7)))/2 | N32: =D32*$B$9*(1-COS(RADIANS($B$7)))/2 | O32: =L32+M32+N32 | P32: =O32*B32 | Q32: =IF(C32=0,0,P32/C32) | R32: =P32*$B$11*$B$12*(1-$B$13)*$B$14 | S32: =R32*$B$10/1000 | T32: =IF(OR(F32<'14_지역·상수'!$H$7,F32>'14_지역·상수'!$H$8),"Kt 범위 검토",IF(OR(K32<0,K32>5),"Rb 검토","정상"))
A33: 12 | B33: =IF($B$6="10년평균",AVERAGEIFS(RawDataKWh[일수],RawDataKWh[월],$A33,RawDataKWh[지역명],$B$5),SUMIFS(RawDataKWh[일수],RawDataKWh[월],$A33,RawDataKWh[연도],VALUE($B$6),RawDataKWh[지역명],$B$5)) | C33: =IF($B$6="10년평균",AVERAGEIFS(RawDataKWh[일사합_kWh_m2],RawDataKWh[월],$A33,RawDataKWh[지역명],$B$5),SUMIFS(RawDataKWh[일사합_kWh_m2],RawDataKWh[월],$A33,RawDataKWh[연도],VALUE($B$6),RawDataKWh[지역명],$B$5)) | D33: =IF(B33=0,0,C33/B33) | E33: =INDEX('15_태양기하'!$H$4:$H$15,MATCH(A33,'15_태양기하'!$A$4:$A$15,0)) | F33: =IF(E33=0,0,D33/E33) | G33: =MAX('14_지역·상수'!$H$7,MIN('14_지역·상수'!$H$8,F33)) | H33: =MAX(0.05,MIN(1,IF(INDEX('15_태양기하'!$D$4:$D$15,MATCH(A33,'15_태양기하'!$A$4:$A$15,0))<=81.4,1.391-3.56*G33+4.189*G33^2-2.137*G33^3,1.311-3.022*G33+3.427*G33^2-1.821*G33^3))) | I33: =D33*H33 | J33: =D33-I33 | K33: =INDEX('15_태양기하'!$G$4:$G$15,MATCH(A33,'15_태양기하'!$A$4:$A$15,0)) | L33: =J33*K33 | M33: =I33*(1+COS(RADIANS($B$7)))/2 | N33: =D33*$B$9*(1-COS(RADIANS($B$7)))/2 | O33: =L33+M33+N33 | P33: =O33*B33 | Q33: =IF(C33=0,0,P33/C33) | R33: =P33*$B$11*$B$12*(1-$B$13)*$B$14 | S33: =R33*$B$10/1000 | T33: =IF(OR(F33<'14_지역·상수'!$H$7,F33>'14_지역·상수'!$H$8),"Kt 범위 검토",IF(OR(K33<0,K33>5),"Rb 검토","정상"))
A34: 연간/평균 | B34: =SUM(B22:B33) | C34: =SUM(C22:C33) | D34: =C34/B34 | E34: =AVERAGE(E22:E33) | F34: =AVERAGE(F22:F33) | G34: =AVERAGE(G22:G33) | H34: =SUMPRODUCT(C22:C33,H22:H33)/SUM(C22:C33) | I34: =SUMPRODUCT(B22:B33,I22:I33)/SUM(B22:B33) | J34: =SUMPRODUCT(B22:B33,J22:J33)/SUM(B22:B33) | K34: =SUMPRODUCT(C22:C33,K22:K33)/SUM(C22:C33) | L34: =SUMPRODUCT(B22:B33,L22:L33)/SUM(B22:B33) | M34: =SUMPRODUCT(B22:B33,M22:M33)/SUM(B22:B33) | N34: =SUMPRODUCT(B22:B33,N22:N33)/SUM(B22:B33) | O34: =SUM(P22:P33)/SUM(B22:B33) | P34: =SUM(P22:P33) | Q34: =P34/C34 | R34: =SUM(R22:R33) | S34: =SUM(S22:S33) | T34: =IF(COUNTIF(T22:T33,"<>정상")=0,"정상","검토 필요")

Sheet 12_월별FACTOR
A1: 월별 경사면 일사량 계산 FACTOR
A2: '11_발전량_모델' 시트에서 사용되는 주요 계수와 월별 값을 한 화면에서 확인합니다. 모든 값은 참조식이며 직접 입력하지 않습니다.
A4: ■ 현재 적용 입력 FACTOR
A5: 지역 | B5: ='11_발전량_모델'!B5 | C5: - | D5: 선택 수평면 일사량 권역
A6: 분석 기준 | B6: ='11_발전량_모델'!B6 | C6: - | D6: 10년평균 또는 개별연도
A7: 위도 φ | B7: ='11_발전량_모델'!B17 | C7: °N | D7: 태양위치 및 H0 계산
A8: 경사각 β | B8: ='11_발전량_모델'!B7 | C8: ° | D8: 모듈면 경사
A9: 방위각 A | B9: ='11_발전량_모델'!B8 | C9: ° | D9: 북0 / 동90 / 남180 / 서270
A10: 지면반사율 ρg | B10: ='11_발전량_모델'!B9 | C10: - | D10: 지면반사 성분
A11: 기준 PR | B11: ='11_발전량_모델'!B11 | C11: - | D11: 종합 시스템 성능계수
A12: 가동률 | B12: ='11_발전량_모델'!B12 | C12: - | D12: 가동 가능률
A13: 출력제한률 | B13: ='11_발전량_모델'!B13 | C13: - | D13: 계통/출력 제한
A14: 기타 보정 | B14: ='11_발전량_모델'!B14 | C14: - | D14: 추가 보정계수
A17: ■ 월별 계산계수
A18: 월 | B18: 대표일 (DOY) | C18: H 수평면 일평균 | D18: H0 대기권외 | E18: Kt | F18: Kt 적용값 | G18: 산란비 | H18: 직달비 | I18: Rb | J18: 천공 View Factor | K18: 지면 View Factor | L18: POA FACTOR | M18: 수평면 월일사량 | N18: 경사면 월일사량 | O18: 특성발전량 | P18: 검토
A19: 1 | B19: =INDEX('15_태양기하'!$B$4:$B$15,MATCH(A19,'15_태양기하'!$A$4:$A$15,0)) | C19: ='11_발전량_모델'!D22 | D19: ='11_발전량_모델'!E22 | E19: ='11_발전량_모델'!F22 | F19: ='11_발전량_모델'!G22 | G19: ='11_발전량_모델'!H22 | H19: =1-G19 | I19: ='11_발전량_모델'!K22 | J19: =(1+COS(RADIANS('11_발전량_모델'!$B$7)))/2 | K19: =(1-COS(RADIANS('11_발전량_모델'!$B$7)))/2 | L19: ='11_발전량_모델'!Q22 | M19: ='11_발전량_모델'!C22 | N19: ='11_발전량_모델'!P22 | O19: ='11_발전량_모델'!R22 | P19: ='11_발전량_모델'!T22
A20: 2 | B20: =INDEX('15_태양기하'!$B$4:$B$15,MATCH(A20,'15_태양기하'!$A$4:$A$15,0)) | C20: ='11_발전량_모델'!D23 | D20: ='11_발전량_모델'!E23 | E20: ='11_발전량_모델'!F23 | F20: ='11_발전량_모델'!G23 | G20: ='11_발전량_모델'!H23 | H20: =1-G20 | I20: ='11_발전량_모델'!K23 | J20: =(1+COS(RADIANS('11_발전량_모델'!$B$7)))/2 | K20: =(1-COS(RADIANS('11_발전량_모델'!$B$7)))/2 | L20: ='11_발전량_모델'!Q23 | M20: ='11_발전량_모델'!C23 | N20: ='11_발전량_모델'!P23 | O20: ='11_발전량_모델'!R23 | P20: ='11_발전량_모델'!T23
A21: 3 | B21: =INDEX('15_태양기하'!$B$4:$B$15,MATCH(A21,'15_태양기하'!$A$4:$A$15,0)) | C21: ='11_발전량_모델'!D24 | D21: ='11_발전량_모델'!E24 | E21: ='11_발전량_모델'!F24 | F21: ='11_발전량_모델'!G24 | G21: ='11_발전량_모델'!H24 | H21: =1-G21 | I21: ='11_발전량_모델'!K24 | J21: =(1+COS(RADIANS('11_발전량_모델'!$B$7)))/2 | K21: =(1-COS(RADIANS('11_발전량_모델'!$B$7)))/2 | L21: ='11_발전량_모델'!Q24 | M21: ='11_발전량_모델'!C24 | N21: ='11_발전량_모델'!P24 | O21: ='11_발전량_모델'!R24 | P21: ='11_발전량_모델'!T24
A22: 4 | B22: =INDEX('15_태양기하'!$B$4:$B$15,MATCH(A22,'15_태양기하'!$A$4:$A$15,0)) | C22: ='11_발전량_모델'!D25 | D22: ='11_발전량_모델'!E25 | E22: ='11_발전량_모델'!F25 | F22: ='11_발전량_모델'!G25 | G22: ='11_발전량_모델'!H25 | H22: =1-G22 | I22: ='11_발전량_모델'!K25 | J22: =(1+COS(RADIANS('11_발전량_모델'!$B$7)))/2 | K22: =(1-COS(RADIANS('11_발전량_모델'!$B$7)))/2 | L22: ='11_발전량_모델'!Q25 | M22: ='11_발전량_모델'!C25 | N22: ='11_발전량_모델'!P25 | O22: ='11_발전량_모델'!R25 | P22: ='11_발전량_모델'!T25
A23: 5 | B23: =INDEX('15_태양기하'!$B$4:$B$15,MATCH(A23,'15_태양기하'!$A$4:$A$15,0)) | C23: ='11_발전량_모델'!D26 | D23: ='11_발전량_모델'!E26 | E23: ='11_발전량_모델'!F26 | F23: ='11_발전량_모델'!G26 | G23: ='11_발전량_모델'!H26 | H23: =1-G23 | I23: ='11_발전량_모델'!K26 | J23: =(1+COS(RADIANS('11_발전량_모델'!$B$7)))/2 | K23: =(1-COS(RADIANS('11_발전량_모델'!$B$7)))/2 | L23: ='11_발전량_모델'!Q26 | M23: ='11_발전량_모델'!C26 | N23: ='11_발전량_모델'!P26 | O23: ='11_발전량_모델'!R26 | P23: ='11_발전량_모델'!T26
A24: 6 | B24: =INDEX('15_태양기하'!$B$4:$B$15,MATCH(A24,'15_태양기하'!$A$4:$A$15,0)) | C24: ='11_발전량_모델'!D27 | D24: ='11_발전량_모델'!E27 | E24: ='11_발전량_모델'!F27 | F24: ='11_발전량_모델'!G27 | G24: ='11_발전량_모델'!H27 | H24: =1-G24 | I24: ='11_발전량_모델'!K27 | J24: =(1+COS(RADIANS('11_발전량_모델'!$B$7)))/2 | K24: =(1-COS(RADIANS('11_발전량_모델'!$B$7)))/2 | L24: ='11_발전량_모델'!Q27 | M24: ='11_발전량_모델'!C27 | N24: ='11_발전량_모델'!P27 | O24: ='11_발전량_모델'!R27 | P24: ='11_발전량_모델'!T27
A25: 7 | B25: =INDEX('15_태양기하'!$B$4:$B$15,MATCH(A25,'15_태양기하'!$A$4:$A$15,0)) | C25: ='11_발전량_모델'!D28 | D25: ='11_발전량_모델'!E28 | E25: ='11_발전량_모델'!F28 | F25: ='11_발전량_모델'!G28 | G25: ='11_발전량_모델'!H28 | H25: =1-G25 | I25: ='11_발전량_모델'!K28 | J25: =(1+COS(RADIANS('11_발전량_모델'!$B$7)))/2 | K25: =(1-COS(RADIANS('11_발전량_모델'!$B$7)))/2 | L25: ='11_발전량_모델'!Q28 | M25: ='11_발전량_모델'!C28 | N25: ='11_발전량_모델'!P28 | O25: ='11_발전량_모델'!R28 | P25: ='11_발전량_모델'!T28
A26: 8 | B26: =INDEX('15_태양기하'!$B$4:$B$15,MATCH(A26,'15_태양기하'!$A$4:$A$15,0)) | C26: ='11_발전량_모델'!D29 | D26: ='11_발전량_모델'!E29 | E26: ='11_발전량_모델'!F29 | F26: ='11_발전량_모델'!G29 | G26: ='11_발전량_모델'!H29 | H26: =1-G26 | I26: ='11_발전량_모델'!K29 | J26: =(1+COS(RADIANS('11_발전량_모델'!$B$7)))/2 | K26: =(1-COS(RADIANS('11_발전량_모델'!$B$7)))/2 | L26: ='11_발전량_모델'!Q29 | M26: ='11_발전량_모델'!C29 | N26: ='11_발전량_모델'!P29 | O26: ='11_발전량_모델'!R29 | P26: ='11_발전량_모델'!T29
A27: 9 | B27: =INDEX('15_태양기하'!$B$4:$B$15,MATCH(A27,'15_태양기하'!$A$4:$A$15,0)) | C27: ='11_발전량_모델'!D30 | D27: ='11_발전량_모델'!E30 | E27: ='11_발전량_모델'!F30 | F27: ='11_발전량_모델'!G30 | G27: ='11_발전량_모델'!H30 | H27: =1-G27 | I27: ='11_발전량_모델'!K30 | J27: =(1+COS(RADIANS('11_발전량_모델'!$B$7)))/2 | K27: =(1-COS(RADIANS('11_발전량_모델'!$B$7)))/2 | L27: ='11_발전량_모델'!Q30 | M27: ='11_발전량_모델'!C30 | N27: ='11_발전량_모델'!P30 | O27: ='11_발전량_모델'!R30 | P27: ='11_발전량_모델'!T30
A28: 10 | B28: =INDEX('15_태양기하'!$B$4:$B$15,MATCH(A28,'15_태양기하'!$A$4:$A$15,0)) | C28: ='11_발전량_모델'!D31 | D28: ='11_발전량_모델'!E31 | E28: ='11_발전량_모델'!F31 | F28: ='11_발전량_모델'!G31 | G28: ='11_발전량_모델'!H31 | H28: =1-G28 | I28: ='11_발전량_모델'!K31 | J28: =(1+COS(RADIANS('11_발전량_모델'!$B$7)))/2 | K28: =(1-COS(RADIANS('11_발전량_모델'!$B$7)))/2 | L28: ='11_발전량_모델'!Q31 | M28: ='11_발전량_모델'!C31 | N28: ='11_발전량_모델'!P31 | O28: ='11_발전량_모델'!R31 | P28: ='11_발전량_모델'!T31
A29: 11 | B29: =INDEX('15_태양기하'!$B$4:$B$15,MATCH(A29,'15_태양기하'!$A$4:$A$15,0)) | C29: ='11_발전량_모델'!D32 | D29: ='11_발전량_모델'!E32 | E29: ='11_발전량_모델'!F32 | F29: ='11_발전량_모델'!G32 | G29: ='11_발전량_모델'!H32 | H29: =1-G29 | I29: ='11_발전량_모델'!K32 | J29: =(1+COS(RADIANS('11_발전량_모델'!$B$7)))/2 | K29: =(1-COS(RADIANS('11_발전량_모델'!$B$7)))/2 | L29: ='11_발전량_모델'!Q32 | M29: ='11_발전량_모델'!C32 | N29: ='11_발전량_모델'!P32 | O29: ='11_발전량_모델'!R32 | P29: ='11_발전량_모델'!T32
A30: 12 | B30: =INDEX('15_태양기하'!$B$4:$B$15,MATCH(A30,'15_태양기하'!$A$4:$A$15,0)) | C30: ='11_발전량_모델'!D33 | D30: ='11_발전량_모델'!E33 | E30: ='11_발전량_모델'!F33 | F30: ='11_발전량_모델'!G33 | G30: ='11_발전량_모델'!H33 | H30: =1-G30 | I30: ='11_발전량_모델'!K33 | J30: =(1+COS(RADIANS('11_발전량_모델'!$B$7)))/2 | K30: =(1-COS(RADIANS('11_발전량_모델'!$B$7)))/2 | L30: ='11_발전량_모델'!Q33 | M30: ='11_발전량_모델'!C33 | N30: ='11_발전량_모델'!P33 | O30: ='11_발전량_모델'!R33 | P30: ='11_발전량_모델'!T33
A33: ■ FACTOR 정의 및 계산식
A34: 기호 | B34: 계산식 | C34: 단위 | D34: 설명
A35: H | B35: 수평면 월일사량 ÷ 일수 | C35: kWh/m²/일 | D35: 지역별 원자료
A36: H0 | B36: (24×60/π)·Gsc·E0·[cosφ cosδ sinωs + ωs sinφ sinδ] | C36: kWh/m²/일 | D36: 대기권외 일사량
A37: Kt | B37: H / H0 | C37: - | D37: 대기 투과 수준
A38: Hd/H | B38: Erbs 월평균 상관식 | C38: - | D38: 산란 성분 비율
A39: Rb | B39: Σmax(cosAOI,0) / Σmax(cosθz,0) | C39: - | D39: 직달 성분의 경사·방위 기하계수
A40: F_sky | B40: (1+cosβ)/2 | C40: - | D40: 등방성 천공산란 View Factor
A41: F_ground | B41: (1-cosβ)/2 | C41: - | D41: 지면 View Factor
A42: POA | B42: Hb×Rb + Hd×F_sky + H×ρg×F_ground | C42: kWh/m²/일 | D42: 경사면 일사량
A43: POA FACTOR | B43: POA 월일사량 / 수평면 월일사량 | C43: 배 | D43: 경사·방위 효과
A44: 특성발전량 | B44: POA × PR × 가동률 × (1-출력제한) × 기타 | C44: kWh/kWp | D44: DC 1 kWp 기준

Sheet 13_시나리오비교
A1: 경사각·방위각 시나리오 비교
A2: 지역·분석기준·PR 등은 '11_발전량_모델' 입력을 공통으로 사용하며, 시나리오별 경사각과 방위각만 바꾸어 비교합니다.
A3: ■ 시나리오별 연간 결과
A4: 시나리오 | B4: 경사각 β [°] | C4: 방위각 A [°] | D4: 연간 수평면 [kWh/m²] | E4: 연간 POA [kWh/m²] | F4: POA FACTOR [배] | G4: 특성발전량 [kWh/kWp] | H4: 발전량 [MWh] | I4: 기본 대비 [%] | J4: 설명
A5: 현재 입력 | B5: ='11_발전량_모델'!B7 | C5: ='11_발전량_모델'!B8 | D5: ='11_발전량_모델'!F5 | E5: =SUMIFS('_시나리오계산'!$O$2:$O$121,'_시나리오계산'!$A$2:$A$121,1) | F5: =IF(D5=0,0,E5/D5) | G5: =SUMIFS('_시나리오계산'!$P$2:$P$121,'_시나리오계산'!$A$2:$A$121,1) | H5: =SUMIFS('_시나리오계산'!$Q$2:$Q$121,'_시나리오계산'!$A$2:$A$121,1) | I5: =IF($H$5=0,0,H5/$H$5-1) | J5: '11_발전량_모델' 시트 입력값
A6: 남향 15° | B6: 15 | C6: 180 | D6: ='11_발전량_모델'!F5 | E6: =SUMIFS('_시나리오계산'!$O$2:$O$121,'_시나리오계산'!$A$2:$A$121,2) | F6: =IF(D6=0,0,E6/D6) | G6: =SUMIFS('_시나리오계산'!$P$2:$P$121,'_시나리오계산'!$A$2:$A$121,2) | H6: =SUMIFS('_시나리오계산'!$Q$2:$Q$121,'_시나리오계산'!$A$2:$A$121,2) | I6: =IF($H$5=0,0,H6/$H$5-1) | J6: 저경사 남향
A7: 남향 20° | B7: 20 | C7: 180 | D7: ='11_발전량_모델'!F5 | E7: =SUMIFS('_시나리오계산'!$O$2:$O$121,'_시나리오계산'!$A$2:$A$121,3) | F7: =IF(D7=0,0,E7/D7) | G7: =SUMIFS('_시나리오계산'!$P$2:$P$121,'_시나리오계산'!$A$2:$A$121,3) | H7: =SUMIFS('_시나리오계산'!$Q$2:$Q$121,'_시나리오계산'!$A$2:$A$121,3) | I7: =IF($H$5=0,0,H7/$H$5-1) | J7: 저경사 남향
A8: 남향 25° | B8: 25 | C8: 180 | D8: ='11_발전량_모델'!F5 | E8: =SUMIFS('_시나리오계산'!$O$2:$O$121,'_시나리오계산'!$A$2:$A$121,4) | F8: =IF(D8=0,0,E8/D8) | G8: =SUMIFS('_시나리오계산'!$P$2:$P$121,'_시나리오계산'!$A$2:$A$121,4) | H8: =SUMIFS('_시나리오계산'!$Q$2:$Q$121,'_시나리오계산'!$A$2:$A$121,4) | I8: =IF($H$5=0,0,H8/$H$5-1) | J8: 국내 일반 고정식 예시
A9: 남향 30° | B9: 30 | C9: 180 | D9: ='11_발전량_모델'!F5 | E9: =SUMIFS('_시나리오계산'!$O$2:$O$121,'_시나리오계산'!$A$2:$A$121,5) | F9: =IF(D9=0,0,E9/D9) | G9: =SUMIFS('_시나리오계산'!$P$2:$P$121,'_시나리오계산'!$A$2:$A$121,5) | H9: =SUMIFS('_시나리오계산'!$Q$2:$Q$121,'_시나리오계산'!$A$2:$A$121,5) | I9: =IF($H$5=0,0,H9/$H$5-1) | J9: 중경사 남향
A10: 남향 35° | B10: 35 | C10: 180 | D10: ='11_발전량_모델'!F5 | E10: =SUMIFS('_시나리오계산'!$O$2:$O$121,'_시나리오계산'!$A$2:$A$121,6) | F10: =IF(D10=0,0,E10/D10) | G10: =SUMIFS('_시나리오계산'!$P$2:$P$121,'_시나리오계산'!$A$2:$A$121,6) | H10: =SUMIFS('_시나리오계산'!$Q$2:$Q$121,'_시나리오계산'!$A$2:$A$121,6) | I10: =IF($H$5=0,0,H10/$H$5-1) | J10: 고경사 남향
A11: 남동향 25° | B11: 25 | C11: 135 | D11: ='11_발전량_모델'!F5 | E11: =SUMIFS('_시나리오계산'!$O$2:$O$121,'_시나리오계산'!$A$2:$A$121,7) | F11: =IF(D11=0,0,E11/D11) | G11: =SUMIFS('_시나리오계산'!$P$2:$P$121,'_시나리오계산'!$A$2:$A$121,7) | H11: =SUMIFS('_시나리오계산'!$Q$2:$Q$121,'_시나리오계산'!$A$2:$A$121,7) | I11: =IF($H$5=0,0,H11/$H$5-1) | J11: 오전 발전 비중 확대
A12: 남서향 25° | B12: 25 | C12: 225 | D12: ='11_발전량_모델'!F5 | E12: =SUMIFS('_시나리오계산'!$O$2:$O$121,'_시나리오계산'!$A$2:$A$121,8) | F12: =IF(D12=0,0,E12/D12) | G12: =SUMIFS('_시나리오계산'!$P$2:$P$121,'_시나리오계산'!$A$2:$A$121,8) | H12: =SUMIFS('_시나리오계산'!$Q$2:$Q$121,'_시나리오계산'!$A$2:$A$121,8) | I12: =IF($H$5=0,0,H12/$H$5-1) | J12: 오후 발전 비중 확대
A13: 동향 20° | B13: 20 | C13: 90 | D13: ='11_발전량_모델'!F5 | E13: =SUMIFS('_시나리오계산'!$O$2:$O$121,'_시나리오계산'!$A$2:$A$121,9) | F13: =IF(D13=0,0,E13/D13) | G13: =SUMIFS('_시나리오계산'!$P$2:$P$121,'_시나리오계산'!$A$2:$A$121,9) | H13: =SUMIFS('_시나리오계산'!$Q$2:$Q$121,'_시나리오계산'!$A$2:$A$121,9) | I13: =IF($H$5=0,0,H13/$H$5-1) | J13: 동향 예시
A14: 서향 20° | B14: 20 | C14: 270 | D14: ='11_발전량_모델'!F5 | E14: =SUMIFS('_시나리오계산'!$O$2:$O$121,'_시나리오계산'!$A$2:$A$121,10) | F14: =IF(D14=0,0,E14/D14) | G14: =SUMIFS('_시나리오계산'!$P$2:$P$121,'_시나리오계산'!$A$2:$A$121,10) | H14: =SUMIFS('_시나리오계산'!$Q$2:$Q$121,'_시나리오계산'!$A$2:$A$121,10) | I14: =IF($H$5=0,0,H14/$H$5-1) | J14: 서향 예시
A16: ※ '기본 대비'는 첫 행(현재 입력) 발전량 대비 증감률입니다. 지역·PR·용량 등 나머지 조건은 모든 시나리오가 동일합니다.

Sheet 14_지역·상수
A1: 지역 대표 위도 및 모델 상수
A2: 지역별 수평면 일사량은 광역권 평균이므로 대표 위도는 초기 검토용입니다. 실제 발전소 위도로 보정하는 것을 권장합니다.
A3: ■ 지역 대표 위도 / ■ 모델 상수·기본값 / ■ 분석 기준 목록
A4: 지역명 | B4: 대표 도시 | C4: 대표 위도 [°N] | D4: 위도 적용 설명 | E4: 비고 | G4: 상수/기본값 | H4: 값 | I4: 단위 | J4: 설명 | K4: 수정 권장 | M4: 분석 기준 목록
A5: 서울경기 | B5: 서울 | C5: 37.5665 | D5: 서울 좌표를 대표값으로 적용 | E5: 현장 위도 입력 권장 | G5: 태양상수 Gsc | H5: 0.082 | I5: MJ/m²/min | J5: 일별 대기권외 수평면 일사량 계산 | K5: 고정 | M5: 10년평균
A6: 강원영동 | B6: 강릉 | C6: 37.7519 | D6: 영동권 대표 도시 | E6: 해안/산악 지형 차이 유의 | G6: 시간 간격 | H6: 0.25 | I6: hour | J6: Rb 적분용 15분 간격 | K6: 고정 | M6: 2016
A7: 강원영서 | B7: 춘천 | C7: 37.8813 | D7: 영서권 대표 도시 | E7: 현장 위도 입력 권장 | G7: Erbs Kt 하한 | H7: 0.3 | I7: - | J7: 월평균 확산분리식 적용 범위 보정 | K7: 고정 | M7: 2017
A8: 충북 | B8: 청주 | C8: 36.6424 | D8: 충북 대표 도시 | E8: 현장 위도 입력 권장 | G8: Erbs Kt 상한 | H8: 0.8 | I8: - | J8: 월평균 확산분리식 적용 범위 보정 | K8: 고정 | M8: 2018
A9: 충남 | B9: 대전 | C9: 36.3504 | D9: 충남권 대표값 | E9: 대전은 행정구역상 별도이나 위도 대표값으로 사용 | G9: 기본 지면반사율 | H9: ='05_FACTOR_기준값'!C11 | I9: - | J9: 일반 토지/잔디 가정 | K9: 05_FACTOR_기준값 참조 | M9: 2019
A10: 경북 | B10: 대구 | C10: 35.8714 | D10: 경북권 대표값 | E10: 대구는 행정구역상 별도이나 위도 대표값으로 사용 | G10: 기본 PR | H10: ='05_FACTOR_기준값'!C6 | I10: - | J10: 온도·인버터·배선·오염·불일치 등 통합 | K10: 05_FACTOR_기준값 참조 | M10: 2020
A11: 경남 | B11: 부산 | C11: 35.1796 | D11: 경남권 대표값 | E11: 부산은 행정구역상 별도이나 위도 대표값으로 사용 | G11: 기본 가동률 | H11: ='05_FACTOR_기준값'!C7 | I11: - | J11: 설비 및 계통 가동 가능률 | K11: 05_FACTOR_기준값 참조 | M11: 2021
A12: 전북 | B12: 전주 | C12: 35.8242 | D12: 전북 대표 도시 | E12: 현장 위도 입력 권장 | G12: 기준 일사강도 | H12: 1 | I12: kW/m² | J12: 특성발전량 환산 기준 | K12: 고정 | M12: 2022
A13: 전남 | B13: 광주 | C13: 35.1595 | D13: 전남권 대표값 | E13: 광주는 행정구역상 별도이나 위도 대표값으로 사용 | M13: 2023
A14: 제주 | B14: 제주 | C14: 33.4996 | D14: 제주권 대표 도시 | E14: 제주 남북부 차이 유의 | M14: 2024
M15: 2025
A17: ※ 지면반사율·PR·가동률의 기본값은 '05_FACTOR_기준값' 시트를 참조합니다(값을 두 곳에서 따로 관리하지 않습니다).
A18: ※ 지역명 목록(A5:A14)과 분석 기준 목록(M5:M15)은 '11_발전량_모델' 시트 입력 셀의 선택 목록으로 사용됩니다.

Sheet 15_태양기하
A1: 태양기하 및 방위·경사 FACTOR 산출
A2: 월 대표일 기준 15분 간격 태양벡터를 적분하여 월별 Rb(경사면/수평면 직달 기하계수)와 대기권외 일사량 H0를 계산합니다.
A3: 월 | B3: 대표일 (DOY) | C3: 적위 δ [°] | D3: 일몰시간각 ωs [°] | E3: Σ cosθz | F3: Σ cosAOI | G3: Rb | H3: H0 [kWh/m²/일] | J3: 적용 입력값
A4: 1 | B4: 17 | C4: =23.45*SIN(RADIANS(360*(284+B4)/365)) | D4: =DEGREES(ACOS(MAX(-1,MIN(1,-TAN(RADIANS('11_발전량_모델'!$B$17))*TAN(RADIANS(C4)))))) | E4: =SUMIFS($N$21:$N$1172,$A$21:$A$1172,A4) | F4: =SUMIFS($O$21:$O$1172,$A$21:$A$1172,A4) | G4: =IF(E4=0,0,F4/E4) | H4: =(24*60/PI())*'14_지역·상수'!$H$5*(1+0.033*COS(RADIANS(360*B4/365)))*(COS(RADIANS('11_발전량_모델'!$B$17))*COS(RADIANS(C4))*SIN(RADIANS(D4))+RADIANS(D4)*SIN(RADIANS('11_발전량_모델'!$B$17))*SIN(RADIANS(C4)))/3.6 | J4: 위도 φ | K4: ='11_발전량_모델'!B17 | L4: °N
A5: 2 | B5: 47 | C5: =23.45*SIN(RADIANS(360*(284+B5)/365)) | D5: =DEGREES(ACOS(MAX(-1,MIN(1,-TAN(RADIANS('11_발전량_모델'!$B$17))*TAN(RADIANS(C5)))))) | E5: =SUMIFS($N$21:$N$1172,$A$21:$A$1172,A5) | F5: =SUMIFS($O$21:$O$1172,$A$21:$A$1172,A5) | G5: =IF(E5=0,0,F5/E5) | H5: =(24*60/PI())*'14_지역·상수'!$H$5*(1+0.033*COS(RADIANS(360*B5/365)))*(COS(RADIANS('11_발전량_모델'!$B$17))*COS(RADIANS(C5))*SIN(RADIANS(D5))+RADIANS(D5)*SIN(RADIANS('11_발전량_모델'!$B$17))*SIN(RADIANS(C5)))/3.6 | J5: 경사각 β | K5: ='11_발전량_모델'!B7 | L5: °
A6: 3 | B6: 75 | C6: =23.45*SIN(RADIANS(360*(284+B6)/365)) | D6: =DEGREES(ACOS(MAX(-1,MIN(1,-TAN(RADIANS('11_발전량_모델'!$B$17))*TAN(RADIANS(C6)))))) | E6: =SUMIFS($N$21:$N$1172,$A$21:$A$1172,A6) | F6: =SUMIFS($O$21:$O$1172,$A$21:$A$1172,A6) | G6: =IF(E6=0,0,F6/E6) | H6: =(24*60/PI())*'14_지역·상수'!$H$5*(1+0.033*COS(RADIANS(360*B6/365)))*(COS(RADIANS('11_발전량_모델'!$B$17))*COS(RADIANS(C6))*SIN(RADIANS(D6))+RADIANS(D6)*SIN(RADIANS('11_발전량_모델'!$B$17))*SIN(RADIANS(C6)))/3.6 | J6: 방위각 A | K6: ='11_발전량_모델'!B8 | L6: °
A7: 4 | B7: 105 | C7: =23.45*SIN(RADIANS(360*(284+B7)/365)) | D7: =DEGREES(ACOS(MAX(-1,MIN(1,-TAN(RADIANS('11_발전량_모델'!$B$17))*TAN(RADIANS(C7)))))) | E7: =SUMIFS($N$21:$N$1172,$A$21:$A$1172,A7) | F7: =SUMIFS($O$21:$O$1172,$A$21:$A$1172,A7) | G7: =IF(E7=0,0,F7/E7) | H7: =(24*60/PI())*'14_지역·상수'!$H$5*(1+0.033*COS(RADIANS(360*B7/365)))*(COS(RADIANS('11_발전량_모델'!$B$17))*COS(RADIANS(C7))*SIN(RADIANS(D7))+RADIANS(D7)*SIN(RADIANS('11_발전량_모델'!$B$17))*SIN(RADIANS(C7)))/3.6
A8: 5 | B8: 135 | C8: =23.45*SIN(RADIANS(360*(284+B8)/365)) | D8: =DEGREES(ACOS(MAX(-1,MIN(1,-TAN(RADIANS('11_발전량_모델'!$B$17))*TAN(RADIANS(C8)))))) | E8: =SUMIFS($N$21:$N$1172,$A$21:$A$1172,A8) | F8: =SUMIFS($O$21:$O$1172,$A$21:$A$1172,A8) | G8: =IF(E8=0,0,F8/E8) | H8: =(24*60/PI())*'14_지역·상수'!$H$5*(1+0.033*COS(RADIANS(360*B8/365)))*(COS(RADIANS('11_발전량_모델'!$B$17))*COS(RADIANS(C8))*SIN(RADIANS(D8))+RADIANS(D8)*SIN(RADIANS('11_발전량_모델'!$B$17))*SIN(RADIANS(C8)))/3.6
A9: 6 | B9: 162 | C9: =23.45*SIN(RADIANS(360*(284+B9)/365)) | D9: =DEGREES(ACOS(MAX(-1,MIN(1,-TAN(RADIANS('11_발전량_모델'!$B$17))*TAN(RADIANS(C9)))))) | E9: =SUMIFS($N$21:$N$1172,$A$21:$A$1172,A9) | F9: =SUMIFS($O$21:$O$1172,$A$21:$A$1172,A9) | G9: =IF(E9=0,0,F9/E9) | H9: =(24*60/PI())*'14_지역·상수'!$H$5*(1+0.033*COS(RADIANS(360*B9/365)))*(COS(RADIANS('11_발전량_모델'!$B$17))*COS(RADIANS(C9))*SIN(RADIANS(D9))+RADIANS(D9)*SIN(RADIANS('11_발전량_모델'!$B$17))*SIN(RADIANS(C9)))/3.6
A10: 7 | B10: 198 | C10: =23.45*SIN(RADIANS(360*(284+B10)/365)) | D10: =DEGREES(ACOS(MAX(-1,MIN(1,-TAN(RADIANS('11_발전량_모델'!$B$17))*TAN(RADIANS(C10)))))) | E10: =SUMIFS($N$21:$N$1172,$A$21:$A$1172,A10) | F10: =SUMIFS($O$21:$O$1172,$A$21:$A$1172,A10) | G10: =IF(E10=0,0,F10/E10) | H10: =(24*60/PI())*'14_지역·상수'!$H$5*(1+0.033*COS(RADIANS(360*B10/365)))*(COS(RADIANS('11_발전량_모델'!$B$17))*COS(RADIANS(C10))*SIN(RADIANS(D10))+RADIANS(D10)*SIN(RADIANS('11_발전량_모델'!$B$17))*SIN(RADIANS(C10)))/3.6
A11: 8 | B11: 228 | C11: =23.45*SIN(RADIANS(360*(284+B11)/365)) | D11: =DEGREES(ACOS(MAX(-1,MIN(1,-TAN(RADIANS('11_발전량_모델'!$B$17))*TAN(RADIANS(C11)))))) | E11: =SUMIFS($N$21:$N$1172,$A$21:$A$1172,A11) | F11: =SUMIFS($O$21:$O$1172,$A$21:$A$1172,A11) | G11: =IF(E11=0,0,F11/E11) | H11: =(24*60/PI())*'14_지역·상수'!$H$5*(1+0.033*COS(RADIANS(360*B11/365)))*(COS(RADIANS('11_발전량_모델'!$B$17))*COS(RADIANS(C11))*SIN(RADIANS(D11))+RADIANS(D11)*SIN(RADIANS('11_발전량_모델'!$B$17))*SIN(RADIANS(C11)))/3.6
A12: 9 | B12: 258 | C12: =23.45*SIN(RADIANS(360*(284+B12)/365)) | D12: =DEGREES(ACOS(MAX(-1,MIN(1,-TAN(RADIANS('11_발전량_모델'!$B$17))*TAN(RADIANS(C12)))))) | E12: =SUMIFS($N$21:$N$1172,$A$21:$A$1172,A12) | F12: =SUMIFS($O$21:$O$1172,$A$21:$A$1172,A12) | G12: =IF(E12=0,0,F12/E12) | H12: =(24*60/PI())*'14_지역·상수'!$H$5*(1+0.033*COS(RADIANS(360*B12/365)))*(COS(RADIANS('11_발전량_모델'!$B$17))*COS(RADIANS(C12))*SIN(RADIANS(D12))+RADIANS(D12)*SIN(RADIANS('11_발전량_모델'!$B$17))*SIN(RADIANS(C12)))/3.6
A13: 10 | B13: 288 | C13: =23.45*SIN(RADIANS(360*(284+B13)/365)) | D13: =DEGREES(ACOS(MAX(-1,MIN(1,-TAN(RADIANS('11_발전량_모델'!$B$17))*TAN(RADIANS(C13)))))) | E13: =SUMIFS($N$21:$N$1172,$A$21:$A$1172,A13) | F13: =SUMIFS($O$21:$O$1172,$A$21:$A$1172,A13) | G13: =IF(E13=0,0,F13/E13) | H13: =(24*60/PI())*'14_지역·상수'!$H$5*(1+0.033*COS(RADIANS(360*B13/365)))*(COS(RADIANS('11_발전량_모델'!$B$17))*COS(RADIANS(C13))*SIN(RADIANS(D13))+RADIANS(D13)*SIN(RADIANS('11_발전량_모델'!$B$17))*SIN(RADIANS(C13)))/3.6
A14: 11 | B14: 318 | C14: =23.45*SIN(RADIANS(360*(284+B14)/365)) | D14: =DEGREES(ACOS(MAX(-1,MIN(1,-TAN(RADIANS('11_발전량_모델'!$B$17))*TAN(RADIANS(C14)))))) | E14: =SUMIFS($N$21:$N$1172,$A$21:$A$1172,A14) | F14: =SUMIFS($O$21:$O$1172,$A$21:$A$1172,A14) | G14: =IF(E14=0,0,F14/E14) | H14: =(24*60/PI())*'14_지역·상수'!$H$5*(1+0.033*COS(RADIANS(360*B14/365)))*(COS(RADIANS('11_발전량_모델'!$B$17))*COS(RADIANS(C14))*SIN(RADIANS(D14))+RADIANS(D14)*SIN(RADIANS('11_발전량_모델'!$B$17))*SIN(RADIANS(C14)))/3.6
A15: 12 | B15: 344 | C15: =23.45*SIN(RADIANS(360*(284+B15)/365)) | D15: =DEGREES(ACOS(MAX(-1,MIN(1,-TAN(RADIANS('11_발전량_모델'!$B$17))*TAN(RADIANS(C15)))))) | E15: =SUMIFS($N$21:$N$1172,$A$21:$A$1172,A15) | F15: =SUMIFS($O$21:$O$1172,$A$21:$A$1172,A15) | G15: =IF(E15=0,0,F15/E15) | H15: =(24*60/PI())*'14_지역·상수'!$H$5*(1+0.033*COS(RADIANS(360*B15/365)))*(COS(RADIANS('11_발전량_모델'!$B$17))*COS(RADIANS(C15))*SIN(RADIANS(D15))+RADIANS(D15)*SIN(RADIANS('11_발전량_모델'!$B$17))*SIN(RADIANS(C15)))/3.6
A18: ■ 15분 간격 태양벡터 적분 상세 (근거 자료 · 행 그룹으로 접혀 있음)
P19: ↓ '13_시나리오비교' 시나리오별 cosAOI⁺ (시나리오 경사각·방위각 적용)
A20: 월 | B20: Step | C20: 태양시 [hour] | D20: DOY | E20: 적위 δ | F20: 시각각 ω | G20: Sun_E | H20: Sun_N | I20: Sun_U=cosθz | J20: Normal_E | K20: Normal_N | L20: Normal_U | M20: cosAOI | N20: cosθz⁺ | O20: cosAOI⁺ | P20: cosAOI⁺ S1 | Q20: cosAOI⁺ S2 | R20: cosAOI⁺ S3 | S20: cosAOI⁺ S4 | T20: cosAOI⁺ S5 | U20: cosAOI⁺ S6 | V20: cosAOI⁺ S7 | W20: cosAOI⁺ S8 | X20: cosAOI⁺ S9 | Y20: cosAOI⁺ S10
A21: 1 | B21: 1 | C21: =(B21-0.5)*'14_지역·상수'!$H$6 | D21: 17 | E21: =INDEX($C$4:$C$15,MATCH(A21,$A$4:$A$15,0)) | F21: =15*(C21-12) | G21: =-COS(RADIANS(E21))*SIN(RADIANS(F21)) | H21: =COS(RADIANS('11_발전량_모델'!$B$17))*SIN(RADIANS(E21))-SIN(RADIANS('11_발전량_모델'!$B$17))*COS(RADIANS(E21))*COS(RADIANS(F21)) | I21: =SIN(RADIANS('11_발전량_모델'!$B$17))*SIN(RADIANS(E21))+COS(RADIANS('11_발전량_모델'!$B$17))*COS(RADIANS(E21))*COS(RADIANS(F21)) | J21: =SIN(RADIANS('11_발전량_모델'!$B$7))*SIN(RADIANS('11_발전량_모델'!$B$8)) | K21: =SIN(RADIANS('11_발전량_모델'!$B$7))*COS(RADIANS('11_발전량_모델'!$B$8)) | L21: =COS(RADIANS('11_발전량_모델'!$B$7)) | M21: =G21*J21+H21*K21+I21*L21 | N21: =MAX(0,I21) | O21: =IF(I21>0,MAX(0,M21),0) | P21: =IF($I21>0,MAX(0,$G21*SIN(RADIANS('13_시나리오비교'!$B$5))*SIN(RADIANS('13_시나리오비교'!$C$5))+$H21*SIN(RADIANS('13_시나리오비교'!$B$5))*COS(RADIANS('13_시나리오비교'!$C$5))+$I21*COS(RADIANS('13_시나리오비교'!$B$5))),0) | Q21: =IF($I21>0,MAX(0,$G21*SIN(RADIANS('13_시나리오비교'!$B$6))*SIN(RADIANS('13_시나리오비교'!$C$6))+$H21*SIN(RADIANS('13_시나리오비교'!$B$6))*COS(RADIANS('13_시나리오비교'!$C$6))+$I21*COS(RADIANS('13_시나리오비교'!$B$6))),0) | R21: =IF($I21>0,MAX(0,$G21*SIN(RADIANS('13_시나리오비교'!$B$7))*SIN(RADIANS('13_시나리오비교'!$C$7))+$H21*SIN(RADIANS('13_시나리오비교'!$B$7))*COS(RADIANS('13_시나리오비교'!$C$7))+$I21*COS(RADIANS('13_시나리오비교'!$B$7))),0) | S21: =IF($I21>0,MAX(0,$G21*SIN(RADIANS('13_시나리오비교'!$B$8))*SIN(RADIANS('13_시나리오비교'!$C$8))+$H21*SIN(RADIANS('13_시나리오비교'!$B$8))*COS(RADIANS('13_시나리오비교'!$C$8))+$I21*COS(RADIANS('13_시나리오비교'!$B$8))),0) | T21: =IF($I21>0,MAX(0,$G21*SIN(RADIANS('13_시나리오비교'!$B$9))*SIN(RADIANS('13_시나리오비교'!$C$9))+$H21*SIN(RADIANS('13_시나리오비교'!$B$9))*COS(RADIANS('13_시나리오비교'!$C$9))+$I21*COS(RADIANS('13_시나리오비교'!$B$9))),0) | U21: =IF($I21>0,MAX(0,$G21*SIN(RADIANS('13_시나리오비교'!$B$10))*SIN(RADIANS('13_시나리오비교'!$C$10))+$H21*SIN(RADIANS('13_시나리오비교'!$B$10))*COS(RADIANS('13_시나리오비교'!$C$10))+$I21*COS(RADIANS('13_시나리오비교'!$B$10))),0) | V21: =IF($I21>0,MAX(0,$G21*SIN(RADIANS('13_시나리오비교'!$B$11))*SIN(RADIANS('13_시나리오비교'!$C$11))+$H21*SIN(RADIANS('13_시나리오비교'!$B$11))*COS(RADIANS('13_시나리오비교'!$C$11))+$I21*COS(RADIANS('13_시나리오비교'!$B$11))),0) | W21: =IF($I21>0,MAX(0,$G21*SIN(RADIANS('13_시나리오비교'!$B$12))*SIN(RADIANS('13_시나리오비교'!$C$12))+$H21*SIN(RADIANS('13_시나리오비교'!$B$12))*COS(RADIANS('13_시나리오비교'!$C$12))+$I21*COS(RADIANS('13_시나리오비교'!$B$12))),0) | X21: =IF($I21>0,MAX(0,$G21*SIN(RADIANS('13_시나리오비교'!$B$13))*SIN(RADIANS('13_시나리오비교'!$C$13))+$H21*SIN(RADIANS('13_시나리오비교'!$B$13))*COS(RADIANS('13_시나리오비교'!$C$13))+$I21*COS(RADIANS('13_시나리오비교'!$B$13))),0) | Y21: =IF($I21>0,MAX(0,$G21*SIN(RADIANS('13_시나리오비교'!$B$14))*SIN(RADIANS('13_시나리오비교'!$C$14))+$H21*SIN(RADIANS('13_시나리오비교'!$B$14))*COS(RADIANS('13_시나리오비교'!$C$14))+$I21*COS(RADIANS('13_시나리오비교'!$B$14))),0)
